2024-08-31 12:57:35,758 loglevel=INFO   logger=uvicorn.error L77   Started server process [28596] serve() call_trace=C:\Users\bharg\AppData\Roaming\Python\Python310\site-packages\uvicorn\server.py
2024-08-31 12:57:35,759 loglevel=INFO   logger=uvicorn.error L46   Waiting for application startup. startup() call_trace=C:\Users\bharg\AppData\Roaming\Python\Python310\site-packages\uvicorn\lifespan\on.py
2024-08-31 12:57:35,760 loglevel=INFO   logger=uvicorn.error L60   Application startup complete. startup() call_trace=C:\Users\bharg\AppData\Roaming\Python\Python310\site-packages\uvicorn\lifespan\on.py
2024-08-31 12:57:35,761 loglevel=INFO   logger=uvicorn.error L219  Uvicorn running on http://0.0.0.0:8000 (Press CTRL+C to quit) _log_started_message() call_trace=C:\Users\bharg\AppData\Roaming\Python\Python310\site-packages\uvicorn\server.py
2024-08-31 13:02:03,118 loglevel=INFO   logger=uvicorn.error L265  Shutting down shutdown() call_trace=C:\Users\bharg\AppData\Roaming\Python\Python310\site-packages\uvicorn\server.py
2024-08-31 13:02:03,231 loglevel=INFO   logger=uvicorn.error L65   Waiting for application shutdown. shutdown() call_trace=C:\Users\bharg\AppData\Roaming\Python\Python310\site-packages\uvicorn\lifespan\on.py
2024-08-31 13:02:03,231 loglevel=INFO   logger=uvicorn.error L76   Application shutdown complete. shutdown() call_trace=C:\Users\bharg\AppData\Roaming\Python\Python310\site-packages\uvicorn\lifespan\on.py
2024-08-31 13:02:03,232 loglevel=INFO   logger=uvicorn.error L87   Finished server process [28596] serve() call_trace=C:\Users\bharg\AppData\Roaming\Python\Python310\site-packages\uvicorn\server.py
2024-08-31 13:02:06,699 loglevel=INFO   logger=uvicorn.error L77   Started server process [21344] serve() call_trace=C:\Users\bharg\AppData\Roaming\Python\Python310\site-packages\uvicorn\server.py
2024-08-31 13:02:06,700 loglevel=INFO   logger=uvicorn.error L46   Waiting for application startup. startup() call_trace=C:\Users\bharg\AppData\Roaming\Python\Python310\site-packages\uvicorn\lifespan\on.py
2024-08-31 13:02:06,700 loglevel=INFO   logger=uvicorn.error L60   Application startup complete. startup() call_trace=C:\Users\bharg\AppData\Roaming\Python\Python310\site-packages\uvicorn\lifespan\on.py
2024-08-31 13:02:06,701 loglevel=INFO   logger=uvicorn.error L219  Uvicorn running on http://0.0.0.0:8000 (Press CTRL+C to quit) _log_started_message() call_trace=C:\Users\bharg\AppData\Roaming\Python\Python310\site-packages\uvicorn\server.py
2024-08-31 13:03:51,882 loglevel=INFO   logger=uvicorn.error L265  Shutting down shutdown() call_trace=C:\Users\bharg\AppData\Roaming\Python\Python310\site-packages\uvicorn\server.py
2024-08-31 13:03:51,991 loglevel=INFO   logger=uvicorn.error L65   Waiting for application shutdown. shutdown() call_trace=C:\Users\bharg\AppData\Roaming\Python\Python310\site-packages\uvicorn\lifespan\on.py
2024-08-31 13:03:51,994 loglevel=INFO   logger=uvicorn.error L76   Application shutdown complete. shutdown() call_trace=C:\Users\bharg\AppData\Roaming\Python\Python310\site-packages\uvicorn\lifespan\on.py
2024-08-31 13:03:51,995 loglevel=INFO   logger=uvicorn.error L87   Finished server process [21344] serve() call_trace=C:\Users\bharg\AppData\Roaming\Python\Python310\site-packages\uvicorn\server.py
2024-08-31 13:03:55,219 loglevel=INFO   logger=uvicorn.error L77   Started server process [31852] serve() call_trace=C:\Users\bharg\AppData\Roaming\Python\Python310\site-packages\uvicorn\server.py
2024-08-31 13:03:55,219 loglevel=INFO   logger=uvicorn.error L46   Waiting for application startup. startup() call_trace=C:\Users\bharg\AppData\Roaming\Python\Python310\site-packages\uvicorn\lifespan\on.py
2024-08-31 13:03:55,220 loglevel=INFO   logger=uvicorn.error L60   Application startup complete. startup() call_trace=C:\Users\bharg\AppData\Roaming\Python\Python310\site-packages\uvicorn\lifespan\on.py
2024-08-31 13:03:55,221 loglevel=INFO   logger=uvicorn.error L219  Uvicorn running on http://0.0.0.0:8000 (Press CTRL+C to quit) _log_started_message() call_trace=C:\Users\bharg\AppData\Roaming\Python\Python310\site-packages\uvicorn\server.py
2024-08-31 13:04:13,824 loglevel=INFO   logger=uvicorn.access L489  127.0.0.1:51302 - "GET /dummy/ HTTP/1.1" 404 send() call_trace=C:\Users\bharg\AppData\Roaming\Python\Python310\site-packages\uvicorn\protocols\http\httptools_impl.py
2024-08-31 13:04:18,724 loglevel=INFO   logger=uvicorn.access L489  127.0.0.1:51302 - "GET /dummy HTTP/1.1" 404 send() call_trace=C:\Users\bharg\AppData\Roaming\Python\Python310\site-packages\uvicorn\protocols\http\httptools_impl.py
2024-08-31 13:04:26,397 loglevel=INFO   logger=uvicorn.access L489  127.0.0.1:51318 - "GET /groups HTTP/1.1" 307 send() call_trace=C:\Users\bharg\AppData\Roaming\Python\Python310\site-packages\uvicorn\protocols\http\httptools_impl.py
2024-08-31 13:04:26,404 loglevel=INFO   logger=uvicorn.access L489  127.0.0.1:51318 - "GET /groups/ HTTP/1.1" 405 send() call_trace=C:\Users\bharg\AppData\Roaming\Python\Python310\site-packages\uvicorn\protocols\http\httptools_impl.py
2024-08-31 13:04:30,903 loglevel=INFO   logger=uvicorn.access L489  127.0.0.1:51318 - "POST /groups HTTP/1.1" 307 send() call_trace=C:\Users\bharg\AppData\Roaming\Python\Python310\site-packages\uvicorn\protocols\http\httptools_impl.py
2024-08-31 13:04:30,956 loglevel=INFO   logger=uvicorn.access L489  127.0.0.1:51318 - "POST /groups/ HTTP/1.1" 200 send() call_trace=C:\Users\bharg\AppData\Roaming\Python\Python310\site-packages\uvicorn\protocols\http\httptools_impl.py
2024-08-31 13:04:57,857 loglevel=INFO   logger=uvicorn.error L265  Shutting down shutdown() call_trace=C:\Users\bharg\AppData\Roaming\Python\Python310\site-packages\uvicorn\server.py
2024-08-31 13:04:57,966 loglevel=INFO   logger=uvicorn.error L65   Waiting for application shutdown. shutdown() call_trace=C:\Users\bharg\AppData\Roaming\Python\Python310\site-packages\uvicorn\lifespan\on.py
2024-08-31 13:04:57,968 loglevel=INFO   logger=uvicorn.error L76   Application shutdown complete. shutdown() call_trace=C:\Users\bharg\AppData\Roaming\Python\Python310\site-packages\uvicorn\lifespan\on.py
2024-08-31 13:04:57,970 loglevel=INFO   logger=uvicorn.error L87   Finished server process [31852] serve() call_trace=C:\Users\bharg\AppData\Roaming\Python\Python310\site-packages\uvicorn\server.py
2024-08-31 13:05:08,310 loglevel=INFO   logger=uvicorn.error L77   Started server process [2988] serve() call_trace=C:\Users\bharg\AppData\Roaming\Python\Python310\site-packages\uvicorn\server.py
2024-08-31 13:05:08,310 loglevel=INFO   logger=uvicorn.error L46   Waiting for application startup. startup() call_trace=C:\Users\bharg\AppData\Roaming\Python\Python310\site-packages\uvicorn\lifespan\on.py
2024-08-31 13:05:08,311 loglevel=INFO   logger=uvicorn.error L60   Application startup complete. startup() call_trace=C:\Users\bharg\AppData\Roaming\Python\Python310\site-packages\uvicorn\lifespan\on.py
2024-08-31 13:05:08,312 loglevel=ERROR  logger=uvicorn.error L169  [Errno 10049] error while attempting to bind on address ('127.0.0.0', 8000): the requested address is not valid in its context startup() call_trace=C:\Users\bharg\AppData\Roaming\Python\Python310\site-packages\uvicorn\server.py
2024-08-31 13:05:08,312 loglevel=INFO   logger=uvicorn.error L65   Waiting for application shutdown. shutdown() call_trace=C:\Users\bharg\AppData\Roaming\Python\Python310\site-packages\uvicorn\lifespan\on.py
2024-08-31 13:05:08,313 loglevel=INFO   logger=uvicorn.error L76   Application shutdown complete. shutdown() call_trace=C:\Users\bharg\AppData\Roaming\Python\Python310\site-packages\uvicorn\lifespan\on.py
2024-08-31 13:05:34,746 loglevel=INFO   logger=uvicorn.error L77   Started server process [21332] serve() call_trace=C:\Users\bharg\AppData\Roaming\Python\Python310\site-packages\uvicorn\server.py
2024-08-31 13:05:34,747 loglevel=INFO   logger=uvicorn.error L46   Waiting for application startup. startup() call_trace=C:\Users\bharg\AppData\Roaming\Python\Python310\site-packages\uvicorn\lifespan\on.py
2024-08-31 13:05:34,747 loglevel=INFO   logger=uvicorn.error L60   Application startup complete. startup() call_trace=C:\Users\bharg\AppData\Roaming\Python\Python310\site-packages\uvicorn\lifespan\on.py
2024-08-31 13:05:34,752 loglevel=INFO   logger=uvicorn.error L219  Uvicorn running on http://localhost:8000 (Press CTRL+C to quit) _log_started_message() call_trace=C:\Users\bharg\AppData\Roaming\Python\Python310\site-packages\uvicorn\server.py
2024-08-31 13:05:40,455 loglevel=INFO   logger=uvicorn.access L489  ::1:51376 - "POST /groups HTTP/1.1" 307 send() call_trace=C:\Users\bharg\AppData\Roaming\Python\Python310\site-packages\uvicorn\protocols\http\httptools_impl.py
2024-08-31 13:05:40,516 loglevel=INFO   logger=uvicorn.access L489  ::1:51376 - "POST /groups/ HTTP/1.1" 200 send() call_trace=C:\Users\bharg\AppData\Roaming\Python\Python310\site-packages\uvicorn\protocols\http\httptools_impl.py
2024-08-31 13:23:30,919 loglevel=INFO   logger=uvicorn.error L265  Shutting down shutdown() call_trace=C:\Users\bharg\AppData\Roaming\Python\Python310\site-packages\uvicorn\server.py
2024-08-31 13:23:31,029 loglevel=INFO   logger=uvicorn.error L65   Waiting for application shutdown. shutdown() call_trace=C:\Users\bharg\AppData\Roaming\Python\Python310\site-packages\uvicorn\lifespan\on.py
2024-08-31 13:23:31,030 loglevel=INFO   logger=uvicorn.error L76   Application shutdown complete. shutdown() call_trace=C:\Users\bharg\AppData\Roaming\Python\Python310\site-packages\uvicorn\lifespan\on.py
2024-08-31 13:23:31,031 loglevel=INFO   logger=uvicorn.error L87   Finished server process [21332] serve() call_trace=C:\Users\bharg\AppData\Roaming\Python\Python310\site-packages\uvicorn\server.py
2024-08-31 13:28:16,584 loglevel=INFO   logger=uvicorn.error L77   Started server process [12172] serve() call_trace=C:\Users\bharg\AppData\Roaming\Python\Python310\site-packages\uvicorn\server.py
2024-08-31 13:28:16,584 loglevel=INFO   logger=uvicorn.error L46   Waiting for application startup. startup() call_trace=C:\Users\bharg\AppData\Roaming\Python\Python310\site-packages\uvicorn\lifespan\on.py
2024-08-31 13:28:16,584 loglevel=INFO   logger=uvicorn.error L60   Application startup complete. startup() call_trace=C:\Users\bharg\AppData\Roaming\Python\Python310\site-packages\uvicorn\lifespan\on.py
2024-08-31 13:28:16,589 loglevel=INFO   logger=uvicorn.error L219  Uvicorn running on http://localhost:8000 (Press CTRL+C to quit) _log_started_message() call_trace=C:\Users\bharg\AppData\Roaming\Python\Python310\site-packages\uvicorn\server.py
2024-08-31 13:29:39,862 loglevel=INFO   logger=uvicorn.access L489  ::1:52315 - "POST /groups HTTP/1.1" 307 send() call_trace=C:\Users\bharg\AppData\Roaming\Python\Python310\site-packages\uvicorn\protocols\http\httptools_impl.py
2024-08-31 13:29:39,887 loglevel=INFO   logger=uvicorn.access L489  ::1:52315 - "POST /groups/ HTTP/1.1" 500 send() call_trace=C:\Users\bharg\AppData\Roaming\Python\Python310\site-packages\uvicorn\protocols\http\httptools_impl.py
2024-08-31 13:29:39,888 loglevel=ERROR  logger=uvicorn.error L424  Exception in ASGI application
 run_asgi() call_trace=C:\Users\bharg\AppData\Roaming\Python\Python310\site-packages\uvicorn\protocols\http\httptools_impl.py
Traceback (most recent call last):
  File "C:\Users\bharg\AppData\Roaming\Python\Python310\site-packages\sqlalchemy\engine\base.py", line 1967, in _exec_single_context
    self.dialect.do_execute(
  File "C:\Users\bharg\AppData\Roaming\Python\Python310\site-packages\sqlalchemy\engine\default.py", line 924, in do_execute
    cursor.execute(statement, parameters)
psycopg2.errors.NotNullViolation: null value in column "creator_id" of relation "groups" violates not-null constraint
DETAIL:  Failing row contains (1, TestGroup, null, This is a test group).


The above exception was the direct cause of the following exception:

Traceback (most recent call last):
  File "C:\Users\bharg\AppData\Roaming\Python\Python310\site-packages\uvicorn\protocols\http\httptools_impl.py", line 419, in run_asgi
    result = await app(  # type: ignore[func-returns-value]
  File "C:\Users\bharg\AppData\Roaming\Python\Python310\site-packages\uvicorn\middleware\proxy_headers.py", line 84, in __call__
    return await self.app(scope, receive, send)
  File "C:\Users\bharg\AppData\Roaming\Python\Python310\site-packages\fastapi\applications.py", line 1054, in __call__
    await super().__call__(scope, receive, send)
  File "C:\Users\bharg\AppData\Roaming\Python\Python310\site-packages\starlette\applications.py", line 123, in __call__
    await self.middleware_stack(scope, receive, send)
  File "C:\Users\bharg\AppData\Roaming\Python\Python310\site-packages\starlette\middleware\errors.py", line 186, in __call__
    raise exc
  File "C:\Users\bharg\AppData\Roaming\Python\Python310\site-packages\starlette\middleware\errors.py", line 164, in __call__
    await self.app(scope, receive, _send)
  File "C:\Users\bharg\AppData\Roaming\Python\Python310\site-packages\starlette\middleware\exceptions.py", line 62, in __call__
    await wrap_app_handling_exceptions(self.app, conn)(scope, receive, send)
  File "C:\Users\bharg\AppData\Roaming\Python\Python310\site-packages\starlette\_exception_handler.py", line 64, in wrapped_app
    raise exc
  File "C:\Users\bharg\AppData\Roaming\Python\Python310\site-packages\starlette\_exception_handler.py", line 53, in wrapped_app
    await app(scope, receive, sender)
  File "C:\Users\bharg\AppData\Roaming\Python\Python310\site-packages\starlette\routing.py", line 758, in __call__
    await self.middleware_stack(scope, receive, send)
  File "C:\Users\bharg\AppData\Roaming\Python\Python310\site-packages\starlette\routing.py", line 778, in app
    await route.handle(scope, receive, send)
  File "C:\Users\bharg\AppData\Roaming\Python\Python310\site-packages\starlette\routing.py", line 299, in handle
    await self.app(scope, receive, send)
  File "C:\Users\bharg\AppData\Roaming\Python\Python310\site-packages\starlette\routing.py", line 79, in app
    await wrap_app_handling_exceptions(app, request)(scope, receive, send)
  File "C:\Users\bharg\AppData\Roaming\Python\Python310\site-packages\starlette\_exception_handler.py", line 64, in wrapped_app
    raise exc
  File "C:\Users\bharg\AppData\Roaming\Python\Python310\site-packages\starlette\_exception_handler.py", line 53, in wrapped_app
    await app(scope, receive, sender)
  File "C:\Users\bharg\AppData\Roaming\Python\Python310\site-packages\starlette\routing.py", line 74, in app
    response = await func(request)
  File "C:\Users\bharg\AppData\Roaming\Python\Python310\site-packages\fastapi\routing.py", line 278, in app
    raw_response = await run_endpoint_function(
  File "C:\Users\bharg\AppData\Roaming\Python\Python310\site-packages\fastapi\routing.py", line 193, in run_endpoint_function
    return await run_in_threadpool(dependant.call, **values)
  File "C:\Users\bharg\AppData\Roaming\Python\Python310\site-packages\starlette\concurrency.py", line 42, in run_in_threadpool
    return await anyio.to_thread.run_sync(func, *args)
  File "C:\ProgramData\anaconda3\lib\site-packages\anyio\to_thread.py", line 28, in run_sync
    return await get_asynclib().run_sync_in_worker_thread(func, *args, cancellable=cancellable,
  File "C:\ProgramData\anaconda3\lib\site-packages\anyio\_backends\_asyncio.py", line 818, in run_sync_in_worker_thread
    return await future
  File "C:\ProgramData\anaconda3\lib\site-packages\anyio\_backends\_asyncio.py", line 754, in run
    result = context.run(func, *args)
  File "C:\Git_Repos\splitwise\src\api\routes\groups.py", line 13, in create_group
    session.commit()
  File "C:\Users\bharg\AppData\Roaming\Python\Python310\site-packages\sqlalchemy\orm\session.py", line 2017, in commit
    trans.commit(_to_root=True)
  File "<string>", line 2, in commit
  File "C:\Users\bharg\AppData\Roaming\Python\Python310\site-packages\sqlalchemy\orm\state_changes.py", line 139, in _go
    ret_value = fn(self, *arg, **kw)
  File "C:\Users\bharg\AppData\Roaming\Python\Python310\site-packages\sqlalchemy\orm\session.py", line 1302, in commit
    self._prepare_impl()
  File "<string>", line 2, in _prepare_impl
  File "C:\Users\bharg\AppData\Roaming\Python\Python310\site-packages\sqlalchemy\orm\state_changes.py", line 139, in _go
    ret_value = fn(self, *arg, **kw)
  File "C:\Users\bharg\AppData\Roaming\Python\Python310\site-packages\sqlalchemy\orm\session.py", line 1277, in _prepare_impl
    self.session.flush()
  File "C:\Users\bharg\AppData\Roaming\Python\Python310\site-packages\sqlalchemy\orm\session.py", line 4341, in flush
    self._flush(objects)
  File "C:\Users\bharg\AppData\Roaming\Python\Python310\site-packages\sqlalchemy\orm\session.py", line 4476, in _flush
    with util.safe_reraise():
  File "C:\Users\bharg\AppData\Roaming\Python\Python310\site-packages\sqlalchemy\util\langhelpers.py", line 146, in __exit__
    raise exc_value.with_traceback(exc_tb)
  File "C:\Users\bharg\AppData\Roaming\Python\Python310\site-packages\sqlalchemy\orm\session.py", line 4437, in _flush
    flush_context.execute()
  File "C:\Users\bharg\AppData\Roaming\Python\Python310\site-packages\sqlalchemy\orm\unitofwork.py", line 466, in execute
    rec.execute(self)
  File "C:\Users\bharg\AppData\Roaming\Python\Python310\site-packages\sqlalchemy\orm\unitofwork.py", line 642, in execute
    util.preloaded.orm_persistence.save_obj(
  File "C:\Users\bharg\AppData\Roaming\Python\Python310\site-packages\sqlalchemy\orm\persistence.py", line 93, in save_obj
    _emit_insert_statements(
  File "C:\Users\bharg\AppData\Roaming\Python\Python310\site-packages\sqlalchemy\orm\persistence.py", line 1233, in _emit_insert_statements
    result = connection.execute(
  File "C:\Users\bharg\AppData\Roaming\Python\Python310\site-packages\sqlalchemy\engine\base.py", line 1418, in execute
    return meth(
  File "C:\Users\bharg\AppData\Roaming\Python\Python310\site-packages\sqlalchemy\sql\elements.py", line 515, in _execute_on_connection
    return connection._execute_clauseelement(
  File "C:\Users\bharg\AppData\Roaming\Python\Python310\site-packages\sqlalchemy\engine\base.py", line 1640, in _execute_clauseelement
    ret = self._execute_context(
  File "C:\Users\bharg\AppData\Roaming\Python\Python310\site-packages\sqlalchemy\engine\base.py", line 1846, in _execute_context
    return self._exec_single_context(
  File "C:\Users\bharg\AppData\Roaming\Python\Python310\site-packages\sqlalchemy\engine\base.py", line 1986, in _exec_single_context
    self._handle_dbapi_exception(
  File "C:\Users\bharg\AppData\Roaming\Python\Python310\site-packages\sqlalchemy\engine\base.py", line 2353, in _handle_dbapi_exception
    raise sqlalchemy_exception.with_traceback(exc_info[2]) from e
  File "C:\Users\bharg\AppData\Roaming\Python\Python310\site-packages\sqlalchemy\engine\base.py", line 1967, in _exec_single_context
    self.dialect.do_execute(
  File "C:\Users\bharg\AppData\Roaming\Python\Python310\site-packages\sqlalchemy\engine\default.py", line 924, in do_execute
    cursor.execute(statement, parameters)
sqlalchemy.exc.IntegrityError: (psycopg2.errors.NotNullViolation) null value in column "creator_id" of relation "groups" violates not-null constraint
DETAIL:  Failing row contains (1, TestGroup, null, This is a test group).

[SQL: INSERT INTO groups (name, creator_id, description) VALUES (%(name)s, %(creator_id)s, %(description)s) RETURNING groups.id]
[parameters: {'name': 'TestGroup', 'creator_id': None, 'description': 'This is a test group'}]
(Background on this error at: https://sqlalche.me/e/20/gkpj)
2024-08-31 13:30:47,594 loglevel=INFO   logger=uvicorn.error L265  Shutting down shutdown() call_trace=C:\Users\bharg\AppData\Roaming\Python\Python310\site-packages\uvicorn\server.py
2024-08-31 13:30:47,703 loglevel=INFO   logger=uvicorn.error L65   Waiting for application shutdown. shutdown() call_trace=C:\Users\bharg\AppData\Roaming\Python\Python310\site-packages\uvicorn\lifespan\on.py
2024-08-31 13:30:47,704 loglevel=INFO   logger=uvicorn.error L76   Application shutdown complete. shutdown() call_trace=C:\Users\bharg\AppData\Roaming\Python\Python310\site-packages\uvicorn\lifespan\on.py
2024-08-31 13:30:47,705 loglevel=INFO   logger=uvicorn.error L87   Finished server process [12172] serve() call_trace=C:\Users\bharg\AppData\Roaming\Python\Python310\site-packages\uvicorn\server.py
2024-08-31 13:30:50,851 loglevel=INFO   logger=uvicorn.error L77   Started server process [4916] serve() call_trace=C:\Users\bharg\AppData\Roaming\Python\Python310\site-packages\uvicorn\server.py
2024-08-31 13:30:50,851 loglevel=INFO   logger=uvicorn.error L46   Waiting for application startup. startup() call_trace=C:\Users\bharg\AppData\Roaming\Python\Python310\site-packages\uvicorn\lifespan\on.py
2024-08-31 13:30:50,852 loglevel=INFO   logger=uvicorn.error L60   Application startup complete. startup() call_trace=C:\Users\bharg\AppData\Roaming\Python\Python310\site-packages\uvicorn\lifespan\on.py
2024-08-31 13:30:50,856 loglevel=INFO   logger=uvicorn.error L219  Uvicorn running on http://localhost:8000 (Press CTRL+C to quit) _log_started_message() call_trace=C:\Users\bharg\AppData\Roaming\Python\Python310\site-packages\uvicorn\server.py
2024-08-31 13:30:55,178 loglevel=INFO   logger=uvicorn.access L489  ::1:52361 - "POST /groups HTTP/1.1" 307 send() call_trace=C:\Users\bharg\AppData\Roaming\Python\Python310\site-packages\uvicorn\protocols\http\httptools_impl.py
2024-08-31 13:30:55,197 loglevel=INFO   logger=uvicorn.access L489  ::1:52361 - "POST /groups/ HTTP/1.1" 500 send() call_trace=C:\Users\bharg\AppData\Roaming\Python\Python310\site-packages\uvicorn\protocols\http\httptools_impl.py
2024-08-31 13:30:55,197 loglevel=ERROR  logger=uvicorn.error L424  Exception in ASGI application
 run_asgi() call_trace=C:\Users\bharg\AppData\Roaming\Python\Python310\site-packages\uvicorn\protocols\http\httptools_impl.py
Traceback (most recent call last):
  File "C:\Users\bharg\AppData\Roaming\Python\Python310\site-packages\sqlalchemy\engine\base.py", line 1967, in _exec_single_context
    self.dialect.do_execute(
  File "C:\Users\bharg\AppData\Roaming\Python\Python310\site-packages\sqlalchemy\engine\default.py", line 924, in do_execute
    cursor.execute(statement, parameters)
psycopg2.errors.ForeignKeyViolation: insert or update on table "groups" violates foreign key constraint "groups_creator_id_fkey"
DETAIL:  Key (creator_id)=(1) is not present in table "users".


The above exception was the direct cause of the following exception:

Traceback (most recent call last):
  File "C:\Users\bharg\AppData\Roaming\Python\Python310\site-packages\uvicorn\protocols\http\httptools_impl.py", line 419, in run_asgi
    result = await app(  # type: ignore[func-returns-value]
  File "C:\Users\bharg\AppData\Roaming\Python\Python310\site-packages\uvicorn\middleware\proxy_headers.py", line 84, in __call__
    return await self.app(scope, receive, send)
  File "C:\Users\bharg\AppData\Roaming\Python\Python310\site-packages\fastapi\applications.py", line 1054, in __call__
    await super().__call__(scope, receive, send)
  File "C:\Users\bharg\AppData\Roaming\Python\Python310\site-packages\starlette\applications.py", line 123, in __call__
    await self.middleware_stack(scope, receive, send)
  File "C:\Users\bharg\AppData\Roaming\Python\Python310\site-packages\starlette\middleware\errors.py", line 186, in __call__
    raise exc
  File "C:\Users\bharg\AppData\Roaming\Python\Python310\site-packages\starlette\middleware\errors.py", line 164, in __call__
    await self.app(scope, receive, _send)
  File "C:\Users\bharg\AppData\Roaming\Python\Python310\site-packages\starlette\middleware\exceptions.py", line 62, in __call__
    await wrap_app_handling_exceptions(self.app, conn)(scope, receive, send)
  File "C:\Users\bharg\AppData\Roaming\Python\Python310\site-packages\starlette\_exception_handler.py", line 64, in wrapped_app
    raise exc
  File "C:\Users\bharg\AppData\Roaming\Python\Python310\site-packages\starlette\_exception_handler.py", line 53, in wrapped_app
    await app(scope, receive, sender)
  File "C:\Users\bharg\AppData\Roaming\Python\Python310\site-packages\starlette\routing.py", line 758, in __call__
    await self.middleware_stack(scope, receive, send)
  File "C:\Users\bharg\AppData\Roaming\Python\Python310\site-packages\starlette\routing.py", line 778, in app
    await route.handle(scope, receive, send)
  File "C:\Users\bharg\AppData\Roaming\Python\Python310\site-packages\starlette\routing.py", line 299, in handle
    await self.app(scope, receive, send)
  File "C:\Users\bharg\AppData\Roaming\Python\Python310\site-packages\starlette\routing.py", line 79, in app
    await wrap_app_handling_exceptions(app, request)(scope, receive, send)
  File "C:\Users\bharg\AppData\Roaming\Python\Python310\site-packages\starlette\_exception_handler.py", line 64, in wrapped_app
    raise exc
  File "C:\Users\bharg\AppData\Roaming\Python\Python310\site-packages\starlette\_exception_handler.py", line 53, in wrapped_app
    await app(scope, receive, sender)
  File "C:\Users\bharg\AppData\Roaming\Python\Python310\site-packages\starlette\routing.py", line 74, in app
    response = await func(request)
  File "C:\Users\bharg\AppData\Roaming\Python\Python310\site-packages\fastapi\routing.py", line 278, in app
    raw_response = await run_endpoint_function(
  File "C:\Users\bharg\AppData\Roaming\Python\Python310\site-packages\fastapi\routing.py", line 193, in run_endpoint_function
    return await run_in_threadpool(dependant.call, **values)
  File "C:\Users\bharg\AppData\Roaming\Python\Python310\site-packages\starlette\concurrency.py", line 42, in run_in_threadpool
    return await anyio.to_thread.run_sync(func, *args)
  File "C:\ProgramData\anaconda3\lib\site-packages\anyio\to_thread.py", line 28, in run_sync
    return await get_asynclib().run_sync_in_worker_thread(func, *args, cancellable=cancellable,
  File "C:\ProgramData\anaconda3\lib\site-packages\anyio\_backends\_asyncio.py", line 818, in run_sync_in_worker_thread
    return await future
  File "C:\ProgramData\anaconda3\lib\site-packages\anyio\_backends\_asyncio.py", line 754, in run
    result = context.run(func, *args)
  File "C:\Git_Repos\splitwise\src\api\routes\groups.py", line 13, in create_group
    session.commit()
  File "C:\Users\bharg\AppData\Roaming\Python\Python310\site-packages\sqlalchemy\orm\session.py", line 2017, in commit
    trans.commit(_to_root=True)
  File "<string>", line 2, in commit
  File "C:\Users\bharg\AppData\Roaming\Python\Python310\site-packages\sqlalchemy\orm\state_changes.py", line 139, in _go
    ret_value = fn(self, *arg, **kw)
  File "C:\Users\bharg\AppData\Roaming\Python\Python310\site-packages\sqlalchemy\orm\session.py", line 1302, in commit
    self._prepare_impl()
  File "<string>", line 2, in _prepare_impl
  File "C:\Users\bharg\AppData\Roaming\Python\Python310\site-packages\sqlalchemy\orm\state_changes.py", line 139, in _go
    ret_value = fn(self, *arg, **kw)
  File "C:\Users\bharg\AppData\Roaming\Python\Python310\site-packages\sqlalchemy\orm\session.py", line 1277, in _prepare_impl
    self.session.flush()
  File "C:\Users\bharg\AppData\Roaming\Python\Python310\site-packages\sqlalchemy\orm\session.py", line 4341, in flush
    self._flush(objects)
  File "C:\Users\bharg\AppData\Roaming\Python\Python310\site-packages\sqlalchemy\orm\session.py", line 4476, in _flush
    with util.safe_reraise():
  File "C:\Users\bharg\AppData\Roaming\Python\Python310\site-packages\sqlalchemy\util\langhelpers.py", line 146, in __exit__
    raise exc_value.with_traceback(exc_tb)
  File "C:\Users\bharg\AppData\Roaming\Python\Python310\site-packages\sqlalchemy\orm\session.py", line 4437, in _flush
    flush_context.execute()
  File "C:\Users\bharg\AppData\Roaming\Python\Python310\site-packages\sqlalchemy\orm\unitofwork.py", line 466, in execute
    rec.execute(self)
  File "C:\Users\bharg\AppData\Roaming\Python\Python310\site-packages\sqlalchemy\orm\unitofwork.py", line 642, in execute
    util.preloaded.orm_persistence.save_obj(
  File "C:\Users\bharg\AppData\Roaming\Python\Python310\site-packages\sqlalchemy\orm\persistence.py", line 93, in save_obj
    _emit_insert_statements(
  File "C:\Users\bharg\AppData\Roaming\Python\Python310\site-packages\sqlalchemy\orm\persistence.py", line 1233, in _emit_insert_statements
    result = connection.execute(
  File "C:\Users\bharg\AppData\Roaming\Python\Python310\site-packages\sqlalchemy\engine\base.py", line 1418, in execute
    return meth(
  File "C:\Users\bharg\AppData\Roaming\Python\Python310\site-packages\sqlalchemy\sql\elements.py", line 515, in _execute_on_connection
    return connection._execute_clauseelement(
  File "C:\Users\bharg\AppData\Roaming\Python\Python310\site-packages\sqlalchemy\engine\base.py", line 1640, in _execute_clauseelement
    ret = self._execute_context(
  File "C:\Users\bharg\AppData\Roaming\Python\Python310\site-packages\sqlalchemy\engine\base.py", line 1846, in _execute_context
    return self._exec_single_context(
  File "C:\Users\bharg\AppData\Roaming\Python\Python310\site-packages\sqlalchemy\engine\base.py", line 1986, in _exec_single_context
    self._handle_dbapi_exception(
  File "C:\Users\bharg\AppData\Roaming\Python\Python310\site-packages\sqlalchemy\engine\base.py", line 2353, in _handle_dbapi_exception
    raise sqlalchemy_exception.with_traceback(exc_info[2]) from e
  File "C:\Users\bharg\AppData\Roaming\Python\Python310\site-packages\sqlalchemy\engine\base.py", line 1967, in _exec_single_context
    self.dialect.do_execute(
  File "C:\Users\bharg\AppData\Roaming\Python\Python310\site-packages\sqlalchemy\engine\default.py", line 924, in do_execute
    cursor.execute(statement, parameters)
sqlalchemy.exc.IntegrityError: (psycopg2.errors.ForeignKeyViolation) insert or update on table "groups" violates foreign key constraint "groups_creator_id_fkey"
DETAIL:  Key (creator_id)=(1) is not present in table "users".

[SQL: INSERT INTO groups (name, creator_id, description) VALUES (%(name)s, %(creator_id)s, %(description)s) RETURNING groups.id]
[parameters: {'name': 'TestGroup', 'creator_id': 1, 'description': 'This is a test group'}]
(Background on this error at: https://sqlalche.me/e/20/gkpj)
2024-08-31 13:35:35,215 loglevel=INFO   logger=uvicorn.access L489  ::1:52727 - "POST /groups HTTP/1.1" 307 send() call_trace=C:\Users\bharg\AppData\Roaming\Python\Python310\site-packages\uvicorn\protocols\http\httptools_impl.py
2024-08-31 13:35:35,229 loglevel=INFO   logger=uvicorn.access L489  ::1:52727 - "POST /groups/ HTTP/1.1" 200 send() call_trace=C:\Users\bharg\AppData\Roaming\Python\Python310\site-packages\uvicorn\protocols\http\httptools_impl.py
2024-08-31 13:36:38,745 loglevel=INFO   logger=uvicorn.access L489  ::1:52903 - "POST /groups HTTP/1.1" 307 send() call_trace=C:\Users\bharg\AppData\Roaming\Python\Python310\site-packages\uvicorn\protocols\http\httptools_impl.py
2024-08-31 13:36:38,757 loglevel=INFO   logger=uvicorn.access L489  ::1:52903 - "POST /groups/ HTTP/1.1" 200 send() call_trace=C:\Users\bharg\AppData\Roaming\Python\Python310\site-packages\uvicorn\protocols\http\httptools_impl.py
2024-08-31 14:00:23,660 loglevel=INFO   logger=uvicorn.access L489  ::1:53324 - "POST /groups HTTP/1.1" 307 send() call_trace=C:\Users\bharg\AppData\Roaming\Python\Python310\site-packages\uvicorn\protocols\http\httptools_impl.py
2024-08-31 14:00:23,683 loglevel=INFO   logger=uvicorn.access L489  ::1:53324 - "POST /groups/ HTTP/1.1" 200 send() call_trace=C:\Users\bharg\AppData\Roaming\Python\Python310\site-packages\uvicorn\protocols\http\httptools_impl.py
2024-08-31 14:00:45,849 loglevel=INFO   logger=uvicorn.error L265  Shutting down shutdown() call_trace=C:\Users\bharg\AppData\Roaming\Python\Python310\site-packages\uvicorn\server.py
2024-08-31 14:00:45,958 loglevel=INFO   logger=uvicorn.error L65   Waiting for application shutdown. shutdown() call_trace=C:\Users\bharg\AppData\Roaming\Python\Python310\site-packages\uvicorn\lifespan\on.py
2024-08-31 14:00:45,961 loglevel=INFO   logger=uvicorn.error L76   Application shutdown complete. shutdown() call_trace=C:\Users\bharg\AppData\Roaming\Python\Python310\site-packages\uvicorn\lifespan\on.py
2024-08-31 14:00:45,963 loglevel=INFO   logger=uvicorn.error L87   Finished server process [4916] serve() call_trace=C:\Users\bharg\AppData\Roaming\Python\Python310\site-packages\uvicorn\server.py
2024-08-31 14:04:37,027 loglevel=INFO   logger=uvicorn.error L77   Started server process [24688] serve() call_trace=C:\Users\bharg\AppData\Roaming\Python\Python310\site-packages\uvicorn\server.py
2024-08-31 14:04:37,027 loglevel=INFO   logger=uvicorn.error L46   Waiting for application startup. startup() call_trace=C:\Users\bharg\AppData\Roaming\Python\Python310\site-packages\uvicorn\lifespan\on.py
2024-08-31 14:04:37,028 loglevel=INFO   logger=uvicorn.error L60   Application startup complete. startup() call_trace=C:\Users\bharg\AppData\Roaming\Python\Python310\site-packages\uvicorn\lifespan\on.py
2024-08-31 14:04:37,032 loglevel=INFO   logger=uvicorn.error L219  Uvicorn running on http://localhost:8000 (Press CTRL+C to quit) _log_started_message() call_trace=C:\Users\bharg\AppData\Roaming\Python\Python310\site-packages\uvicorn\server.py
2024-08-31 14:04:53,352 loglevel=INFO   logger=uvicorn.access L489  ::1:53501 - "POST /groups HTTP/1.1" 307 send() call_trace=C:\Users\bharg\AppData\Roaming\Python\Python310\site-packages\uvicorn\protocols\http\httptools_impl.py
2024-08-31 14:04:53,398 loglevel=INFO   logger=uvicorn.access L489  ::1:53501 - "POST /groups/ HTTP/1.1" 200 send() call_trace=C:\Users\bharg\AppData\Roaming\Python\Python310\site-packages\uvicorn\protocols\http\httptools_impl.py
2024-08-31 14:21:24,562 loglevel=INFO   logger=uvicorn.error L265  Shutting down shutdown() call_trace=C:\Users\bharg\AppData\Roaming\Python\Python310\site-packages\uvicorn\server.py
2024-08-31 14:21:24,670 loglevel=INFO   logger=uvicorn.error L65   Waiting for application shutdown. shutdown() call_trace=C:\Users\bharg\AppData\Roaming\Python\Python310\site-packages\uvicorn\lifespan\on.py
2024-08-31 14:21:24,671 loglevel=INFO   logger=uvicorn.error L76   Application shutdown complete. shutdown() call_trace=C:\Users\bharg\AppData\Roaming\Python\Python310\site-packages\uvicorn\lifespan\on.py
2024-08-31 14:21:24,672 loglevel=INFO   logger=uvicorn.error L87   Finished server process [24688] serve() call_trace=C:\Users\bharg\AppData\Roaming\Python\Python310\site-packages\uvicorn\server.py
2024-08-31 14:21:28,213 loglevel=INFO   logger=uvicorn.error L77   Started server process [8236] serve() call_trace=C:\Users\bharg\AppData\Roaming\Python\Python310\site-packages\uvicorn\server.py
2024-08-31 14:21:28,214 loglevel=INFO   logger=uvicorn.error L46   Waiting for application startup. startup() call_trace=C:\Users\bharg\AppData\Roaming\Python\Python310\site-packages\uvicorn\lifespan\on.py
2024-08-31 14:21:28,214 loglevel=INFO   logger=uvicorn.error L60   Application startup complete. startup() call_trace=C:\Users\bharg\AppData\Roaming\Python\Python310\site-packages\uvicorn\lifespan\on.py
2024-08-31 14:21:28,218 loglevel=INFO   logger=uvicorn.error L219  Uvicorn running on http://localhost:8000 (Press CTRL+C to quit) _log_started_message() call_trace=C:\Users\bharg\AppData\Roaming\Python\Python310\site-packages\uvicorn\server.py
2024-08-31 14:22:30,731 loglevel=INFO   logger=uvicorn.access L489  ::1:53995 - "GET /groups HTTP/1.1" 307 send() call_trace=C:\Users\bharg\AppData\Roaming\Python\Python310\site-packages\uvicorn\protocols\http\httptools_impl.py
2024-08-31 14:22:30,750 loglevel=INFO   logger=uvicorn.access L489  ::1:53995 - "GET /groups/ HTTP/1.1" 200 send() call_trace=C:\Users\bharg\AppData\Roaming\Python\Python310\site-packages\uvicorn\protocols\http\httptools_impl.py
2024-08-31 14:22:39,211 loglevel=INFO   logger=uvicorn.access L489  ::1:54004 - "GET /groups HTTP/1.1" 307 send() call_trace=C:\Users\bharg\AppData\Roaming\Python\Python310\site-packages\uvicorn\protocols\http\httptools_impl.py
2024-08-31 14:22:39,227 loglevel=INFO   logger=uvicorn.access L489  ::1:54004 - "GET /groups/ HTTP/1.1" 200 send() call_trace=C:\Users\bharg\AppData\Roaming\Python\Python310\site-packages\uvicorn\protocols\http\httptools_impl.py
2024-08-31 14:22:46,262 loglevel=INFO   logger=uvicorn.access L489  ::1:54010 - "GET /groups HTTP/1.1" 307 send() call_trace=C:\Users\bharg\AppData\Roaming\Python\Python310\site-packages\uvicorn\protocols\http\httptools_impl.py
2024-08-31 14:22:46,268 loglevel=INFO   logger=uvicorn.access L489  ::1:54010 - "GET /groups/ HTTP/1.1" 200 send() call_trace=C:\Users\bharg\AppData\Roaming\Python\Python310\site-packages\uvicorn\protocols\http\httptools_impl.py
2024-08-31 14:40:37,182 loglevel=INFO   logger=uvicorn.error L265  Shutting down shutdown() call_trace=C:\Users\bharg\AppData\Roaming\Python\Python310\site-packages\uvicorn\server.py
2024-08-31 14:40:37,294 loglevel=INFO   logger=uvicorn.error L65   Waiting for application shutdown. shutdown() call_trace=C:\Users\bharg\AppData\Roaming\Python\Python310\site-packages\uvicorn\lifespan\on.py
2024-08-31 14:40:37,295 loglevel=INFO   logger=uvicorn.error L76   Application shutdown complete. shutdown() call_trace=C:\Users\bharg\AppData\Roaming\Python\Python310\site-packages\uvicorn\lifespan\on.py
2024-08-31 14:40:37,296 loglevel=INFO   logger=uvicorn.error L87   Finished server process [8236] serve() call_trace=C:\Users\bharg\AppData\Roaming\Python\Python310\site-packages\uvicorn\server.py
2024-08-31 14:40:40,822 loglevel=INFO   logger=uvicorn.error L77   Started server process [31184] serve() call_trace=C:\Users\bharg\AppData\Roaming\Python\Python310\site-packages\uvicorn\server.py
2024-08-31 14:40:40,823 loglevel=INFO   logger=uvicorn.error L46   Waiting for application startup. startup() call_trace=C:\Users\bharg\AppData\Roaming\Python\Python310\site-packages\uvicorn\lifespan\on.py
2024-08-31 14:40:40,823 loglevel=INFO   logger=uvicorn.error L60   Application startup complete. startup() call_trace=C:\Users\bharg\AppData\Roaming\Python\Python310\site-packages\uvicorn\lifespan\on.py
2024-08-31 14:40:40,828 loglevel=INFO   logger=uvicorn.error L219  Uvicorn running on http://localhost:8000 (Press CTRL+C to quit) _log_started_message() call_trace=C:\Users\bharg\AppData\Roaming\Python\Python310\site-packages\uvicorn\server.py
2024-08-31 14:41:00,386 loglevel=INFO   logger=uvicorn.access L489  ::1:55967 - "GET /groups/3 HTTP/1.1" 500 send() call_trace=C:\Users\bharg\AppData\Roaming\Python\Python310\site-packages\uvicorn\protocols\http\httptools_impl.py
2024-08-31 14:41:00,387 loglevel=ERROR  logger=uvicorn.error L424  Exception in ASGI application
 run_asgi() call_trace=C:\Users\bharg\AppData\Roaming\Python\Python310\site-packages\uvicorn\protocols\http\httptools_impl.py
Traceback (most recent call last):
  File "C:\Users\bharg\AppData\Roaming\Python\Python310\site-packages\uvicorn\protocols\http\httptools_impl.py", line 419, in run_asgi
    result = await app(  # type: ignore[func-returns-value]
  File "C:\Users\bharg\AppData\Roaming\Python\Python310\site-packages\uvicorn\middleware\proxy_headers.py", line 84, in __call__
    return await self.app(scope, receive, send)
  File "C:\Users\bharg\AppData\Roaming\Python\Python310\site-packages\fastapi\applications.py", line 1054, in __call__
    await super().__call__(scope, receive, send)
  File "C:\Users\bharg\AppData\Roaming\Python\Python310\site-packages\starlette\applications.py", line 123, in __call__
    await self.middleware_stack(scope, receive, send)
  File "C:\Users\bharg\AppData\Roaming\Python\Python310\site-packages\starlette\middleware\errors.py", line 186, in __call__
    raise exc
  File "C:\Users\bharg\AppData\Roaming\Python\Python310\site-packages\starlette\middleware\errors.py", line 164, in __call__
    await self.app(scope, receive, _send)
  File "C:\Users\bharg\AppData\Roaming\Python\Python310\site-packages\starlette\middleware\exceptions.py", line 62, in __call__
    await wrap_app_handling_exceptions(self.app, conn)(scope, receive, send)
  File "C:\Users\bharg\AppData\Roaming\Python\Python310\site-packages\starlette\_exception_handler.py", line 64, in wrapped_app
    raise exc
  File "C:\Users\bharg\AppData\Roaming\Python\Python310\site-packages\starlette\_exception_handler.py", line 53, in wrapped_app
    await app(scope, receive, sender)
  File "C:\Users\bharg\AppData\Roaming\Python\Python310\site-packages\starlette\routing.py", line 758, in __call__
    await self.middleware_stack(scope, receive, send)
  File "C:\Users\bharg\AppData\Roaming\Python\Python310\site-packages\starlette\routing.py", line 778, in app
    await route.handle(scope, receive, send)
  File "C:\Users\bharg\AppData\Roaming\Python\Python310\site-packages\starlette\routing.py", line 299, in handle
    await self.app(scope, receive, send)
  File "C:\Users\bharg\AppData\Roaming\Python\Python310\site-packages\starlette\routing.py", line 79, in app
    await wrap_app_handling_exceptions(app, request)(scope, receive, send)
  File "C:\Users\bharg\AppData\Roaming\Python\Python310\site-packages\starlette\_exception_handler.py", line 64, in wrapped_app
    raise exc
  File "C:\Users\bharg\AppData\Roaming\Python\Python310\site-packages\starlette\_exception_handler.py", line 53, in wrapped_app
    await app(scope, receive, sender)
  File "C:\Users\bharg\AppData\Roaming\Python\Python310\site-packages\starlette\routing.py", line 74, in app
    response = await func(request)
  File "C:\Users\bharg\AppData\Roaming\Python\Python310\site-packages\fastapi\routing.py", line 278, in app
    raw_response = await run_endpoint_function(
  File "C:\Users\bharg\AppData\Roaming\Python\Python310\site-packages\fastapi\routing.py", line 193, in run_endpoint_function
    return await run_in_threadpool(dependant.call, **values)
  File "C:\Users\bharg\AppData\Roaming\Python\Python310\site-packages\starlette\concurrency.py", line 42, in run_in_threadpool
    return await anyio.to_thread.run_sync(func, *args)
  File "C:\ProgramData\anaconda3\lib\site-packages\anyio\to_thread.py", line 28, in run_sync
    return await get_asynclib().run_sync_in_worker_thread(func, *args, cancellable=cancellable,
  File "C:\ProgramData\anaconda3\lib\site-packages\anyio\_backends\_asyncio.py", line 818, in run_sync_in_worker_thread
    return await future
  File "C:\ProgramData\anaconda3\lib\site-packages\anyio\_backends\_asyncio.py", line 754, in run
    result = context.run(func, *args)
  File "C:\Git_Repos\splitwise\src\api\routes\groups.py", line 39, in get_group
    group = session.scalars(stmt).one()
  File "C:\Users\bharg\AppData\Roaming\Python\Python310\site-packages\sqlalchemy\engine\result.py", line 1810, in one
    return self._only_one_row(
  File "C:\Users\bharg\AppData\Roaming\Python\Python310\site-packages\sqlalchemy\engine\result.py", line 752, in _only_one_row
    raise exc.NoResultFound(
sqlalchemy.exc.NoResultFound: No row was found when one was required
2024-08-31 14:41:27,022 loglevel=INFO   logger=uvicorn.access L489  ::1:56013 - "GET /groups/3 HTTP/1.1" 500 send() call_trace=C:\Users\bharg\AppData\Roaming\Python\Python310\site-packages\uvicorn\protocols\http\httptools_impl.py
2024-08-31 14:41:27,022 loglevel=ERROR  logger=uvicorn.error L424  Exception in ASGI application
 run_asgi() call_trace=C:\Users\bharg\AppData\Roaming\Python\Python310\site-packages\uvicorn\protocols\http\httptools_impl.py
Traceback (most recent call last):
  File "C:\Users\bharg\AppData\Roaming\Python\Python310\site-packages\uvicorn\protocols\http\httptools_impl.py", line 419, in run_asgi
    result = await app(  # type: ignore[func-returns-value]
  File "C:\Users\bharg\AppData\Roaming\Python\Python310\site-packages\uvicorn\middleware\proxy_headers.py", line 84, in __call__
    return await self.app(scope, receive, send)
  File "C:\Users\bharg\AppData\Roaming\Python\Python310\site-packages\fastapi\applications.py", line 1054, in __call__
    await super().__call__(scope, receive, send)
  File "C:\Users\bharg\AppData\Roaming\Python\Python310\site-packages\starlette\applications.py", line 123, in __call__
    await self.middleware_stack(scope, receive, send)
  File "C:\Users\bharg\AppData\Roaming\Python\Python310\site-packages\starlette\middleware\errors.py", line 186, in __call__
    raise exc
  File "C:\Users\bharg\AppData\Roaming\Python\Python310\site-packages\starlette\middleware\errors.py", line 164, in __call__
    await self.app(scope, receive, _send)
  File "C:\Users\bharg\AppData\Roaming\Python\Python310\site-packages\starlette\middleware\exceptions.py", line 62, in __call__
    await wrap_app_handling_exceptions(self.app, conn)(scope, receive, send)
  File "C:\Users\bharg\AppData\Roaming\Python\Python310\site-packages\starlette\_exception_handler.py", line 64, in wrapped_app
    raise exc
  File "C:\Users\bharg\AppData\Roaming\Python\Python310\site-packages\starlette\_exception_handler.py", line 53, in wrapped_app
    await app(scope, receive, sender)
  File "C:\Users\bharg\AppData\Roaming\Python\Python310\site-packages\starlette\routing.py", line 758, in __call__
    await self.middleware_stack(scope, receive, send)
  File "C:\Users\bharg\AppData\Roaming\Python\Python310\site-packages\starlette\routing.py", line 778, in app
    await route.handle(scope, receive, send)
  File "C:\Users\bharg\AppData\Roaming\Python\Python310\site-packages\starlette\routing.py", line 299, in handle
    await self.app(scope, receive, send)
  File "C:\Users\bharg\AppData\Roaming\Python\Python310\site-packages\starlette\routing.py", line 79, in app
    await wrap_app_handling_exceptions(app, request)(scope, receive, send)
  File "C:\Users\bharg\AppData\Roaming\Python\Python310\site-packages\starlette\_exception_handler.py", line 64, in wrapped_app
    raise exc
  File "C:\Users\bharg\AppData\Roaming\Python\Python310\site-packages\starlette\_exception_handler.py", line 53, in wrapped_app
    await app(scope, receive, sender)
  File "C:\Users\bharg\AppData\Roaming\Python\Python310\site-packages\starlette\routing.py", line 74, in app
    response = await func(request)
  File "C:\Users\bharg\AppData\Roaming\Python\Python310\site-packages\fastapi\routing.py", line 278, in app
    raw_response = await run_endpoint_function(
  File "C:\Users\bharg\AppData\Roaming\Python\Python310\site-packages\fastapi\routing.py", line 193, in run_endpoint_function
    return await run_in_threadpool(dependant.call, **values)
  File "C:\Users\bharg\AppData\Roaming\Python\Python310\site-packages\starlette\concurrency.py", line 42, in run_in_threadpool
    return await anyio.to_thread.run_sync(func, *args)
  File "C:\ProgramData\anaconda3\lib\site-packages\anyio\to_thread.py", line 28, in run_sync
    return await get_asynclib().run_sync_in_worker_thread(func, *args, cancellable=cancellable,
  File "C:\ProgramData\anaconda3\lib\site-packages\anyio\_backends\_asyncio.py", line 818, in run_sync_in_worker_thread
    return await future
  File "C:\ProgramData\anaconda3\lib\site-packages\anyio\_backends\_asyncio.py", line 754, in run
    result = context.run(func, *args)
  File "C:\Git_Repos\splitwise\src\api\routes\groups.py", line 39, in get_group
    group = session.scalars(stmt).one()
  File "C:\Users\bharg\AppData\Roaming\Python\Python310\site-packages\sqlalchemy\engine\result.py", line 1810, in one
    return self._only_one_row(
  File "C:\Users\bharg\AppData\Roaming\Python\Python310\site-packages\sqlalchemy\engine\result.py", line 752, in _only_one_row
    raise exc.NoResultFound(
sqlalchemy.exc.NoResultFound: No row was found when one was required
2024-08-31 14:42:00,328 loglevel=INFO   logger=uvicorn.access L489  ::1:56051 - "GET /groups/3 HTTP/1.1" 200 send() call_trace=C:\Users\bharg\AppData\Roaming\Python\Python310\site-packages\uvicorn\protocols\http\httptools_impl.py
2024-08-31 14:42:06,914 loglevel=INFO   logger=uvicorn.access L489  ::1:56058 - "GET /groups/4 HTTP/1.1" 200 send() call_trace=C:\Users\bharg\AppData\Roaming\Python\Python310\site-packages\uvicorn\protocols\http\httptools_impl.py
2024-08-31 14:42:11,545 loglevel=INFO   logger=uvicorn.access L489  ::1:56058 - "GET /groups/5 HTTP/1.1" 200 send() call_trace=C:\Users\bharg\AppData\Roaming\Python\Python310\site-packages\uvicorn\protocols\http\httptools_impl.py
2024-08-31 14:42:18,386 loglevel=INFO   logger=uvicorn.access L489  ::1:56066 - "GET /groups/5 HTTP/1.1" 500 send() call_trace=C:\Users\bharg\AppData\Roaming\Python\Python310\site-packages\uvicorn\protocols\http\httptools_impl.py
2024-08-31 14:42:18,389 loglevel=ERROR  logger=uvicorn.error L424  Exception in ASGI application
 run_asgi() call_trace=C:\Users\bharg\AppData\Roaming\Python\Python310\site-packages\uvicorn\protocols\http\httptools_impl.py
Traceback (most recent call last):
  File "C:\Users\bharg\AppData\Roaming\Python\Python310\site-packages\uvicorn\protocols\http\httptools_impl.py", line 419, in run_asgi
    result = await app(  # type: ignore[func-returns-value]
  File "C:\Users\bharg\AppData\Roaming\Python\Python310\site-packages\uvicorn\middleware\proxy_headers.py", line 84, in __call__
    return await self.app(scope, receive, send)
  File "C:\Users\bharg\AppData\Roaming\Python\Python310\site-packages\fastapi\applications.py", line 1054, in __call__
    await super().__call__(scope, receive, send)
  File "C:\Users\bharg\AppData\Roaming\Python\Python310\site-packages\starlette\applications.py", line 123, in __call__
    await self.middleware_stack(scope, receive, send)
  File "C:\Users\bharg\AppData\Roaming\Python\Python310\site-packages\starlette\middleware\errors.py", line 186, in __call__
    raise exc
  File "C:\Users\bharg\AppData\Roaming\Python\Python310\site-packages\starlette\middleware\errors.py", line 164, in __call__
    await self.app(scope, receive, _send)
  File "C:\Users\bharg\AppData\Roaming\Python\Python310\site-packages\starlette\middleware\exceptions.py", line 62, in __call__
    await wrap_app_handling_exceptions(self.app, conn)(scope, receive, send)
  File "C:\Users\bharg\AppData\Roaming\Python\Python310\site-packages\starlette\_exception_handler.py", line 64, in wrapped_app
    raise exc
  File "C:\Users\bharg\AppData\Roaming\Python\Python310\site-packages\starlette\_exception_handler.py", line 53, in wrapped_app
    await app(scope, receive, sender)
  File "C:\Users\bharg\AppData\Roaming\Python\Python310\site-packages\starlette\routing.py", line 758, in __call__
    await self.middleware_stack(scope, receive, send)
  File "C:\Users\bharg\AppData\Roaming\Python\Python310\site-packages\starlette\routing.py", line 778, in app
    await route.handle(scope, receive, send)
  File "C:\Users\bharg\AppData\Roaming\Python\Python310\site-packages\starlette\routing.py", line 299, in handle
    await self.app(scope, receive, send)
  File "C:\Users\bharg\AppData\Roaming\Python\Python310\site-packages\starlette\routing.py", line 79, in app
    await wrap_app_handling_exceptions(app, request)(scope, receive, send)
  File "C:\Users\bharg\AppData\Roaming\Python\Python310\site-packages\starlette\_exception_handler.py", line 64, in wrapped_app
    raise exc
  File "C:\Users\bharg\AppData\Roaming\Python\Python310\site-packages\starlette\_exception_handler.py", line 53, in wrapped_app
    await app(scope, receive, sender)
  File "C:\Users\bharg\AppData\Roaming\Python\Python310\site-packages\starlette\routing.py", line 74, in app
    response = await func(request)
  File "C:\Users\bharg\AppData\Roaming\Python\Python310\site-packages\fastapi\routing.py", line 278, in app
    raw_response = await run_endpoint_function(
  File "C:\Users\bharg\AppData\Roaming\Python\Python310\site-packages\fastapi\routing.py", line 193, in run_endpoint_function
    return await run_in_threadpool(dependant.call, **values)
  File "C:\Users\bharg\AppData\Roaming\Python\Python310\site-packages\starlette\concurrency.py", line 42, in run_in_threadpool
    return await anyio.to_thread.run_sync(func, *args)
  File "C:\ProgramData\anaconda3\lib\site-packages\anyio\to_thread.py", line 28, in run_sync
    return await get_asynclib().run_sync_in_worker_thread(func, *args, cancellable=cancellable,
  File "C:\ProgramData\anaconda3\lib\site-packages\anyio\_backends\_asyncio.py", line 818, in run_sync_in_worker_thread
    return await future
  File "C:\ProgramData\anaconda3\lib\site-packages\anyio\_backends\_asyncio.py", line 754, in run
    result = context.run(func, *args)
  File "C:\Git_Repos\splitwise\src\api\routes\groups.py", line 39, in get_group
    group = session.scalars(stmt).one()
  File "C:\Users\bharg\AppData\Roaming\Python\Python310\site-packages\sqlalchemy\engine\result.py", line 1810, in one
    return self._only_one_row(
  File "C:\Users\bharg\AppData\Roaming\Python\Python310\site-packages\sqlalchemy\engine\result.py", line 752, in _only_one_row
    raise exc.NoResultFound(
sqlalchemy.exc.NoResultFound: No row was found when one was required
2024-08-31 14:42:22,483 loglevel=INFO   logger=uvicorn.access L489  ::1:56079 - "GET /groups/6 HTTP/1.1" 200 send() call_trace=C:\Users\bharg\AppData\Roaming\Python\Python310\site-packages\uvicorn\protocols\http\httptools_impl.py
2024-08-31 14:50:19,505 loglevel=INFO   logger=uvicorn.error L265  Shutting down shutdown() call_trace=C:\Users\bharg\AppData\Roaming\Python\Python310\site-packages\uvicorn\server.py
2024-08-31 14:50:19,616 loglevel=INFO   logger=uvicorn.error L65   Waiting for application shutdown. shutdown() call_trace=C:\Users\bharg\AppData\Roaming\Python\Python310\site-packages\uvicorn\lifespan\on.py
2024-08-31 14:50:19,617 loglevel=INFO   logger=uvicorn.error L76   Application shutdown complete. shutdown() call_trace=C:\Users\bharg\AppData\Roaming\Python\Python310\site-packages\uvicorn\lifespan\on.py
2024-08-31 14:50:19,617 loglevel=INFO   logger=uvicorn.error L87   Finished server process [31184] serve() call_trace=C:\Users\bharg\AppData\Roaming\Python\Python310\site-packages\uvicorn\server.py
2024-08-31 14:50:32,241 loglevel=INFO   logger=uvicorn.error L77   Started server process [22940] serve() call_trace=C:\Users\bharg\AppData\Roaming\Python\Python310\site-packages\uvicorn\server.py
2024-08-31 14:50:32,241 loglevel=INFO   logger=uvicorn.error L46   Waiting for application startup. startup() call_trace=C:\Users\bharg\AppData\Roaming\Python\Python310\site-packages\uvicorn\lifespan\on.py
2024-08-31 14:50:32,242 loglevel=INFO   logger=uvicorn.error L60   Application startup complete. startup() call_trace=C:\Users\bharg\AppData\Roaming\Python\Python310\site-packages\uvicorn\lifespan\on.py
2024-08-31 14:50:32,246 loglevel=INFO   logger=uvicorn.error L219  Uvicorn running on http://localhost:8000 (Press CTRL+C to quit) _log_started_message() call_trace=C:\Users\bharg\AppData\Roaming\Python\Python310\site-packages\uvicorn\server.py
2024-08-31 14:50:47,216 loglevel=INFO   logger=uvicorn.access L489  ::1:56238 - "GET /groups HTTP/1.1" 307 send() call_trace=C:\Users\bharg\AppData\Roaming\Python\Python310\site-packages\uvicorn\protocols\http\httptools_impl.py
2024-08-31 14:50:47,247 loglevel=INFO   logger=uvicorn.access L489  ::1:56238 - "GET /groups/ HTTP/1.1" 500 send() call_trace=C:\Users\bharg\AppData\Roaming\Python\Python310\site-packages\uvicorn\protocols\http\httptools_impl.py
2024-08-31 14:50:47,248 loglevel=ERROR  logger=uvicorn.error L424  Exception in ASGI application
 run_asgi() call_trace=C:\Users\bharg\AppData\Roaming\Python\Python310\site-packages\uvicorn\protocols\http\httptools_impl.py
Traceback (most recent call last):
  File "C:\Users\bharg\AppData\Roaming\Python\Python310\site-packages\uvicorn\protocols\http\httptools_impl.py", line 419, in run_asgi
    result = await app(  # type: ignore[func-returns-value]
  File "C:\Users\bharg\AppData\Roaming\Python\Python310\site-packages\uvicorn\middleware\proxy_headers.py", line 84, in __call__
    return await self.app(scope, receive, send)
  File "C:\Users\bharg\AppData\Roaming\Python\Python310\site-packages\fastapi\applications.py", line 1054, in __call__
    await super().__call__(scope, receive, send)
  File "C:\Users\bharg\AppData\Roaming\Python\Python310\site-packages\starlette\applications.py", line 123, in __call__
    await self.middleware_stack(scope, receive, send)
  File "C:\Users\bharg\AppData\Roaming\Python\Python310\site-packages\starlette\middleware\errors.py", line 186, in __call__
    raise exc
  File "C:\Users\bharg\AppData\Roaming\Python\Python310\site-packages\starlette\middleware\errors.py", line 164, in __call__
    await self.app(scope, receive, _send)
  File "C:\Users\bharg\AppData\Roaming\Python\Python310\site-packages\starlette\middleware\exceptions.py", line 62, in __call__
    await wrap_app_handling_exceptions(self.app, conn)(scope, receive, send)
  File "C:\Users\bharg\AppData\Roaming\Python\Python310\site-packages\starlette\_exception_handler.py", line 64, in wrapped_app
    raise exc
  File "C:\Users\bharg\AppData\Roaming\Python\Python310\site-packages\starlette\_exception_handler.py", line 53, in wrapped_app
    await app(scope, receive, sender)
  File "C:\Users\bharg\AppData\Roaming\Python\Python310\site-packages\starlette\routing.py", line 758, in __call__
    await self.middleware_stack(scope, receive, send)
  File "C:\Users\bharg\AppData\Roaming\Python\Python310\site-packages\starlette\routing.py", line 778, in app
    await route.handle(scope, receive, send)
  File "C:\Users\bharg\AppData\Roaming\Python\Python310\site-packages\starlette\routing.py", line 299, in handle
    await self.app(scope, receive, send)
  File "C:\Users\bharg\AppData\Roaming\Python\Python310\site-packages\starlette\routing.py", line 79, in app
    await wrap_app_handling_exceptions(app, request)(scope, receive, send)
  File "C:\Users\bharg\AppData\Roaming\Python\Python310\site-packages\starlette\_exception_handler.py", line 64, in wrapped_app
    raise exc
  File "C:\Users\bharg\AppData\Roaming\Python\Python310\site-packages\starlette\_exception_handler.py", line 53, in wrapped_app
    await app(scope, receive, sender)
  File "C:\Users\bharg\AppData\Roaming\Python\Python310\site-packages\starlette\routing.py", line 74, in app
    response = await func(request)
  File "C:\Users\bharg\AppData\Roaming\Python\Python310\site-packages\fastapi\routing.py", line 278, in app
    raw_response = await run_endpoint_function(
  File "C:\Users\bharg\AppData\Roaming\Python\Python310\site-packages\fastapi\routing.py", line 193, in run_endpoint_function
    return await run_in_threadpool(dependant.call, **values)
  File "C:\Users\bharg\AppData\Roaming\Python\Python310\site-packages\starlette\concurrency.py", line 42, in run_in_threadpool
    return await anyio.to_thread.run_sync(func, *args)
  File "C:\ProgramData\anaconda3\lib\site-packages\anyio\to_thread.py", line 28, in run_sync
    return await get_asynclib().run_sync_in_worker_thread(func, *args, cancellable=cancellable,
  File "C:\ProgramData\anaconda3\lib\site-packages\anyio\_backends\_asyncio.py", line 818, in run_sync_in_worker_thread
    return await future
  File "C:\ProgramData\anaconda3\lib\site-packages\anyio\_backends\_asyncio.py", line 754, in run
    result = context.run(func, *args)
  File "C:\Git_Repos\splitwise\src\api\routes\groups.py", line 34, in get_all_groups
    groups_list.append(GroupResponse(name = group.name, description= group.description))
  File "C:\Users\bharg\AppData\Roaming\Python\Python310\site-packages\pydantic\main.py", line 171, in __init__
    self.__pydantic_validator__.validate_python(data, self_instance=self)
pydantic_core._pydantic_core.ValidationError: 1 validation error for GroupResponse
id
  Field required [type=missing, input_value={'name': 'TestGroup 4', '...This is a test group 4'}, input_type=dict]
    For further information visit https://errors.pydantic.dev/2.6/v/missing
2024-08-31 14:51:29,757 loglevel=INFO   logger=uvicorn.error L265  Shutting down shutdown() call_trace=C:\Users\bharg\AppData\Roaming\Python\Python310\site-packages\uvicorn\server.py
2024-08-31 14:51:29,868 loglevel=INFO   logger=uvicorn.error L65   Waiting for application shutdown. shutdown() call_trace=C:\Users\bharg\AppData\Roaming\Python\Python310\site-packages\uvicorn\lifespan\on.py
2024-08-31 14:51:29,869 loglevel=INFO   logger=uvicorn.error L76   Application shutdown complete. shutdown() call_trace=C:\Users\bharg\AppData\Roaming\Python\Python310\site-packages\uvicorn\lifespan\on.py
2024-08-31 14:51:29,869 loglevel=INFO   logger=uvicorn.error L87   Finished server process [22940] serve() call_trace=C:\Users\bharg\AppData\Roaming\Python\Python310\site-packages\uvicorn\server.py
2024-08-31 14:51:33,611 loglevel=INFO   logger=uvicorn.error L77   Started server process [35964] serve() call_trace=C:\Users\bharg\AppData\Roaming\Python\Python310\site-packages\uvicorn\server.py
2024-08-31 14:51:33,612 loglevel=INFO   logger=uvicorn.error L46   Waiting for application startup. startup() call_trace=C:\Users\bharg\AppData\Roaming\Python\Python310\site-packages\uvicorn\lifespan\on.py
2024-08-31 14:51:33,612 loglevel=INFO   logger=uvicorn.error L60   Application startup complete. startup() call_trace=C:\Users\bharg\AppData\Roaming\Python\Python310\site-packages\uvicorn\lifespan\on.py
2024-08-31 14:51:33,618 loglevel=INFO   logger=uvicorn.error L219  Uvicorn running on http://localhost:8000 (Press CTRL+C to quit) _log_started_message() call_trace=C:\Users\bharg\AppData\Roaming\Python\Python310\site-packages\uvicorn\server.py
2024-08-31 14:51:42,041 loglevel=INFO   logger=uvicorn.access L489  ::1:56280 - "GET /groups HTTP/1.1" 307 send() call_trace=C:\Users\bharg\AppData\Roaming\Python\Python310\site-packages\uvicorn\protocols\http\httptools_impl.py
2024-08-31 14:51:42,062 loglevel=INFO   logger=uvicorn.access L489  ::1:56280 - "GET /groups/ HTTP/1.1" 200 send() call_trace=C:\Users\bharg\AppData\Roaming\Python\Python310\site-packages\uvicorn\protocols\http\httptools_impl.py
2024-08-31 14:51:47,375 loglevel=INFO   logger=uvicorn.access L489  ::1:56284 - "GET /groups HTTP/1.1" 307 send() call_trace=C:\Users\bharg\AppData\Roaming\Python\Python310\site-packages\uvicorn\protocols\http\httptools_impl.py
2024-08-31 14:51:47,398 loglevel=INFO   logger=uvicorn.access L489  ::1:56284 - "GET /groups/ HTTP/1.1" 200 send() call_trace=C:\Users\bharg\AppData\Roaming\Python\Python310\site-packages\uvicorn\protocols\http\httptools_impl.py
2024-08-31 14:52:34,723 loglevel=INFO   logger=uvicorn.error L265  Shutting down shutdown() call_trace=C:\Users\bharg\AppData\Roaming\Python\Python310\site-packages\uvicorn\server.py
2024-08-31 14:52:34,835 loglevel=INFO   logger=uvicorn.error L65   Waiting for application shutdown. shutdown() call_trace=C:\Users\bharg\AppData\Roaming\Python\Python310\site-packages\uvicorn\lifespan\on.py
2024-08-31 14:52:34,836 loglevel=INFO   logger=uvicorn.error L76   Application shutdown complete. shutdown() call_trace=C:\Users\bharg\AppData\Roaming\Python\Python310\site-packages\uvicorn\lifespan\on.py
2024-08-31 14:52:34,836 loglevel=INFO   logger=uvicorn.error L87   Finished server process [35964] serve() call_trace=C:\Users\bharg\AppData\Roaming\Python\Python310\site-packages\uvicorn\server.py
2024-08-31 14:52:40,145 loglevel=INFO   logger=uvicorn.error L77   Started server process [14496] serve() call_trace=C:\Users\bharg\AppData\Roaming\Python\Python310\site-packages\uvicorn\server.py
2024-08-31 14:52:40,145 loglevel=INFO   logger=uvicorn.error L46   Waiting for application startup. startup() call_trace=C:\Users\bharg\AppData\Roaming\Python\Python310\site-packages\uvicorn\lifespan\on.py
2024-08-31 14:52:40,146 loglevel=INFO   logger=uvicorn.error L60   Application startup complete. startup() call_trace=C:\Users\bharg\AppData\Roaming\Python\Python310\site-packages\uvicorn\lifespan\on.py
2024-08-31 14:52:40,153 loglevel=INFO   logger=uvicorn.error L219  Uvicorn running on http://localhost:8000 (Press CTRL+C to quit) _log_started_message() call_trace=C:\Users\bharg\AppData\Roaming\Python\Python310\site-packages\uvicorn\server.py
2024-08-31 14:52:48,030 loglevel=INFO   logger=uvicorn.access L489  ::1:56327 - "GET /groups HTTP/1.1" 307 send() call_trace=C:\Users\bharg\AppData\Roaming\Python\Python310\site-packages\uvicorn\protocols\http\httptools_impl.py
2024-08-31 14:52:48,051 loglevel=INFO   logger=uvicorn.access L489  ::1:56327 - "GET /groups/ HTTP/1.1" 200 send() call_trace=C:\Users\bharg\AppData\Roaming\Python\Python310\site-packages\uvicorn\protocols\http\httptools_impl.py
2024-08-31 14:53:19,913 loglevel=INFO   logger=uvicorn.error L265  Shutting down shutdown() call_trace=C:\Users\bharg\AppData\Roaming\Python\Python310\site-packages\uvicorn\server.py
2024-08-31 14:53:20,024 loglevel=INFO   logger=uvicorn.error L65   Waiting for application shutdown. shutdown() call_trace=C:\Users\bharg\AppData\Roaming\Python\Python310\site-packages\uvicorn\lifespan\on.py
2024-08-31 14:53:20,025 loglevel=INFO   logger=uvicorn.error L76   Application shutdown complete. shutdown() call_trace=C:\Users\bharg\AppData\Roaming\Python\Python310\site-packages\uvicorn\lifespan\on.py
2024-08-31 14:53:20,026 loglevel=INFO   logger=uvicorn.error L87   Finished server process [14496] serve() call_trace=C:\Users\bharg\AppData\Roaming\Python\Python310\site-packages\uvicorn\server.py
2024-08-31 14:53:23,416 loglevel=INFO   logger=uvicorn.error L77   Started server process [10652] serve() call_trace=C:\Users\bharg\AppData\Roaming\Python\Python310\site-packages\uvicorn\server.py
2024-08-31 14:53:23,417 loglevel=INFO   logger=uvicorn.error L46   Waiting for application startup. startup() call_trace=C:\Users\bharg\AppData\Roaming\Python\Python310\site-packages\uvicorn\lifespan\on.py
2024-08-31 14:53:23,418 loglevel=INFO   logger=uvicorn.error L60   Application startup complete. startup() call_trace=C:\Users\bharg\AppData\Roaming\Python\Python310\site-packages\uvicorn\lifespan\on.py
2024-08-31 14:53:23,425 loglevel=INFO   logger=uvicorn.error L219  Uvicorn running on http://localhost:8000 (Press CTRL+C to quit) _log_started_message() call_trace=C:\Users\bharg\AppData\Roaming\Python\Python310\site-packages\uvicorn\server.py
2024-08-31 14:53:33,382 loglevel=INFO   logger=uvicorn.access L489  ::1:56363 - "GET /groups HTTP/1.1" 307 send() call_trace=C:\Users\bharg\AppData\Roaming\Python\Python310\site-packages\uvicorn\protocols\http\httptools_impl.py
2024-08-31 14:53:33,420 loglevel=INFO   logger=uvicorn.access L489  ::1:56363 - "GET /groups/ HTTP/1.1" 200 send() call_trace=C:\Users\bharg\AppData\Roaming\Python\Python310\site-packages\uvicorn\protocols\http\httptools_impl.py
2024-08-31 14:53:41,818 loglevel=INFO   logger=uvicorn.access L489  ::1:56372 - "GET /groups/5 HTTP/1.1" 200 send() call_trace=C:\Users\bharg\AppData\Roaming\Python\Python310\site-packages\uvicorn\protocols\http\httptools_impl.py
2024-08-31 14:53:46,073 loglevel=INFO   logger=uvicorn.access L489  ::1:56372 - "GET /groups HTTP/1.1" 307 send() call_trace=C:\Users\bharg\AppData\Roaming\Python\Python310\site-packages\uvicorn\protocols\http\httptools_impl.py
2024-08-31 14:53:46,081 loglevel=INFO   logger=uvicorn.access L489  ::1:56372 - "GET /groups/ HTTP/1.1" 200 send() call_trace=C:\Users\bharg\AppData\Roaming\Python\Python310\site-packages\uvicorn\protocols\http\httptools_impl.py
2024-08-31 15:25:09,327 loglevel=INFO   logger=uvicorn.error L265  Shutting down shutdown() call_trace=C:\Users\bharg\AppData\Roaming\Python\Python310\site-packages\uvicorn\server.py
2024-08-31 15:25:09,437 loglevel=INFO   logger=uvicorn.error L65   Waiting for application shutdown. shutdown() call_trace=C:\Users\bharg\AppData\Roaming\Python\Python310\site-packages\uvicorn\lifespan\on.py
2024-08-31 15:25:09,438 loglevel=INFO   logger=uvicorn.error L76   Application shutdown complete. shutdown() call_trace=C:\Users\bharg\AppData\Roaming\Python\Python310\site-packages\uvicorn\lifespan\on.py
2024-08-31 15:25:09,439 loglevel=INFO   logger=uvicorn.error L87   Finished server process [10652] serve() call_trace=C:\Users\bharg\AppData\Roaming\Python\Python310\site-packages\uvicorn\server.py
2024-08-31 15:30:36,170 loglevel=INFO   logger=uvicorn.error L77   Started server process [31508] serve() call_trace=C:\Users\bharg\AppData\Roaming\Python\Python310\site-packages\uvicorn\server.py
2024-08-31 15:30:36,170 loglevel=INFO   logger=uvicorn.error L46   Waiting for application startup. startup() call_trace=C:\Users\bharg\AppData\Roaming\Python\Python310\site-packages\uvicorn\lifespan\on.py
2024-08-31 15:30:36,171 loglevel=INFO   logger=uvicorn.error L60   Application startup complete. startup() call_trace=C:\Users\bharg\AppData\Roaming\Python\Python310\site-packages\uvicorn\lifespan\on.py
2024-08-31 15:30:36,180 loglevel=INFO   logger=uvicorn.error L219  Uvicorn running on http://localhost:8000 (Press CTRL+C to quit) _log_started_message() call_trace=C:\Users\bharg\AppData\Roaming\Python\Python310\site-packages\uvicorn\server.py
2024-08-31 15:31:27,449 loglevel=INFO   logger=uvicorn.access L489  ::1:57092 - "GET /groups HTTP/1.1" 307 send() call_trace=C:\Users\bharg\AppData\Roaming\Python\Python310\site-packages\uvicorn\protocols\http\httptools_impl.py
2024-08-31 15:31:27,471 loglevel=INFO   logger=uvicorn.access L489  ::1:57092 - "GET /groups/ HTTP/1.1" 200 send() call_trace=C:\Users\bharg\AppData\Roaming\Python\Python310\site-packages\uvicorn\protocols\http\httptools_impl.py
2024-08-31 15:31:34,080 loglevel=INFO   logger=uvicorn.access L489  ::1:57095 - "GET /groups HTTP/1.1" 307 send() call_trace=C:\Users\bharg\AppData\Roaming\Python\Python310\site-packages\uvicorn\protocols\http\httptools_impl.py
2024-08-31 15:31:34,104 loglevel=INFO   logger=uvicorn.access L489  ::1:57095 - "GET /groups/ HTTP/1.1" 200 send() call_trace=C:\Users\bharg\AppData\Roaming\Python\Python310\site-packages\uvicorn\protocols\http\httptools_impl.py
2024-08-31 15:32:57,941 loglevel=INFO   logger=uvicorn.access L489  127.0.0.1:57132 - "GET /groups/3 HTTP/1.1" 200 send() call_trace=C:\Users\bharg\AppData\Roaming\Python\Python310\site-packages\uvicorn\protocols\http\httptools_impl.py
2024-08-31 15:34:38,528 loglevel=INFO   logger=uvicorn.access L489  ::1:57191 - "DELETE /groups/3 HTTP/1.1" 200 send() call_trace=C:\Users\bharg\AppData\Roaming\Python\Python310\site-packages\uvicorn\protocols\http\httptools_impl.py
2024-08-31 15:36:13,906 loglevel=INFO   logger=uvicorn.access L489  127.0.0.1:57228 - "POST /groups/ HTTP/1.1" 200 send() call_trace=C:\Users\bharg\AppData\Roaming\Python\Python310\site-packages\uvicorn\protocols\http\httptools_impl.py
2024-08-31 15:36:31,233 loglevel=INFO   logger=uvicorn.access L489  ::1:57240 - "GET /groups HTTP/1.1" 307 send() call_trace=C:\Users\bharg\AppData\Roaming\Python\Python310\site-packages\uvicorn\protocols\http\httptools_impl.py
2024-08-31 15:36:31,250 loglevel=INFO   logger=uvicorn.access L489  ::1:57240 - "GET /groups/ HTTP/1.1" 200 send() call_trace=C:\Users\bharg\AppData\Roaming\Python\Python310\site-packages\uvicorn\protocols\http\httptools_impl.py
2024-08-31 15:38:06,316 loglevel=INFO   logger=uvicorn.access L489  127.0.0.1:57286 - "PUT /groups/7 HTTP/1.1" 500 send() call_trace=C:\Users\bharg\AppData\Roaming\Python\Python310\site-packages\uvicorn\protocols\http\httptools_impl.py
2024-08-31 15:38:06,317 loglevel=ERROR  logger=uvicorn.error L424  Exception in ASGI application
 run_asgi() call_trace=C:\Users\bharg\AppData\Roaming\Python\Python310\site-packages\uvicorn\protocols\http\httptools_impl.py
Traceback (most recent call last):
  File "C:\Users\bharg\AppData\Roaming\Python\Python310\site-packages\uvicorn\protocols\http\httptools_impl.py", line 419, in run_asgi
    result = await app(  # type: ignore[func-returns-value]
  File "C:\Users\bharg\AppData\Roaming\Python\Python310\site-packages\uvicorn\middleware\proxy_headers.py", line 84, in __call__
    return await self.app(scope, receive, send)
  File "C:\Users\bharg\AppData\Roaming\Python\Python310\site-packages\fastapi\applications.py", line 1054, in __call__
    await super().__call__(scope, receive, send)
  File "C:\Users\bharg\AppData\Roaming\Python\Python310\site-packages\starlette\applications.py", line 123, in __call__
    await self.middleware_stack(scope, receive, send)
  File "C:\Users\bharg\AppData\Roaming\Python\Python310\site-packages\starlette\middleware\errors.py", line 186, in __call__
    raise exc
  File "C:\Users\bharg\AppData\Roaming\Python\Python310\site-packages\starlette\middleware\errors.py", line 164, in __call__
    await self.app(scope, receive, _send)
  File "C:\Users\bharg\AppData\Roaming\Python\Python310\site-packages\starlette\middleware\exceptions.py", line 62, in __call__
    await wrap_app_handling_exceptions(self.app, conn)(scope, receive, send)
  File "C:\Users\bharg\AppData\Roaming\Python\Python310\site-packages\starlette\_exception_handler.py", line 64, in wrapped_app
    raise exc
  File "C:\Users\bharg\AppData\Roaming\Python\Python310\site-packages\starlette\_exception_handler.py", line 53, in wrapped_app
    await app(scope, receive, sender)
  File "C:\Users\bharg\AppData\Roaming\Python\Python310\site-packages\starlette\routing.py", line 758, in __call__
    await self.middleware_stack(scope, receive, send)
  File "C:\Users\bharg\AppData\Roaming\Python\Python310\site-packages\starlette\routing.py", line 778, in app
    await route.handle(scope, receive, send)
  File "C:\Users\bharg\AppData\Roaming\Python\Python310\site-packages\starlette\routing.py", line 299, in handle
    await self.app(scope, receive, send)
  File "C:\Users\bharg\AppData\Roaming\Python\Python310\site-packages\starlette\routing.py", line 79, in app
    await wrap_app_handling_exceptions(app, request)(scope, receive, send)
  File "C:\Users\bharg\AppData\Roaming\Python\Python310\site-packages\starlette\_exception_handler.py", line 64, in wrapped_app
    raise exc
  File "C:\Users\bharg\AppData\Roaming\Python\Python310\site-packages\starlette\_exception_handler.py", line 53, in wrapped_app
    await app(scope, receive, sender)
  File "C:\Users\bharg\AppData\Roaming\Python\Python310\site-packages\starlette\routing.py", line 74, in app
    response = await func(request)
  File "C:\Users\bharg\AppData\Roaming\Python\Python310\site-packages\fastapi\routing.py", line 278, in app
    raw_response = await run_endpoint_function(
  File "C:\Users\bharg\AppData\Roaming\Python\Python310\site-packages\fastapi\routing.py", line 193, in run_endpoint_function
    return await run_in_threadpool(dependant.call, **values)
  File "C:\Users\bharg\AppData\Roaming\Python\Python310\site-packages\starlette\concurrency.py", line 42, in run_in_threadpool
    return await anyio.to_thread.run_sync(func, *args)
  File "C:\ProgramData\anaconda3\lib\site-packages\anyio\to_thread.py", line 28, in run_sync
    return await get_asynclib().run_sync_in_worker_thread(func, *args, cancellable=cancellable,
  File "C:\ProgramData\anaconda3\lib\site-packages\anyio\_backends\_asyncio.py", line 818, in run_sync_in_worker_thread
    return await future
  File "C:\ProgramData\anaconda3\lib\site-packages\anyio\_backends\_asyncio.py", line 754, in run
    result = context.run(func, *args)
  File "C:\Git_Repos\splitwise\src\api\routes\groups.py", line 59, in edit_group
    group.users = users
  File "C:\Users\bharg\AppData\Roaming\Python\Python310\site-packages\sqlalchemy\orm\attributes.py", line 537, in __set__
    self.impl.set(
  File "C:\Users\bharg\AppData\Roaming\Python\Python310\site-packages\sqlalchemy\orm\attributes.py", line 1941, in set
    raise TypeError(
TypeError: Incompatible collection type: Select is not list-like
2024-08-31 15:40:04,802 loglevel=INFO   logger=uvicorn.error L265  Shutting down shutdown() call_trace=C:\Users\bharg\AppData\Roaming\Python\Python310\site-packages\uvicorn\server.py
2024-08-31 15:40:04,910 loglevel=INFO   logger=uvicorn.error L65   Waiting for application shutdown. shutdown() call_trace=C:\Users\bharg\AppData\Roaming\Python\Python310\site-packages\uvicorn\lifespan\on.py
2024-08-31 15:40:04,911 loglevel=INFO   logger=uvicorn.error L76   Application shutdown complete. shutdown() call_trace=C:\Users\bharg\AppData\Roaming\Python\Python310\site-packages\uvicorn\lifespan\on.py
2024-08-31 15:40:04,912 loglevel=INFO   logger=uvicorn.error L87   Finished server process [31508] serve() call_trace=C:\Users\bharg\AppData\Roaming\Python\Python310\site-packages\uvicorn\server.py
2024-08-31 15:40:08,984 loglevel=INFO   logger=uvicorn.error L77   Started server process [14516] serve() call_trace=C:\Users\bharg\AppData\Roaming\Python\Python310\site-packages\uvicorn\server.py
2024-08-31 15:40:08,985 loglevel=INFO   logger=uvicorn.error L46   Waiting for application startup. startup() call_trace=C:\Users\bharg\AppData\Roaming\Python\Python310\site-packages\uvicorn\lifespan\on.py
2024-08-31 15:40:08,986 loglevel=INFO   logger=uvicorn.error L60   Application startup complete. startup() call_trace=C:\Users\bharg\AppData\Roaming\Python\Python310\site-packages\uvicorn\lifespan\on.py
2024-08-31 15:40:08,993 loglevel=INFO   logger=uvicorn.error L219  Uvicorn running on http://localhost:8000 (Press CTRL+C to quit) _log_started_message() call_trace=C:\Users\bharg\AppData\Roaming\Python\Python310\site-packages\uvicorn\server.py
2024-08-31 15:40:19,761 loglevel=INFO   logger=uvicorn.access L489  127.0.0.1:57391 - "PUT /groups/7 HTTP/1.1" 200 send() call_trace=C:\Users\bharg\AppData\Roaming\Python\Python310\site-packages\uvicorn\protocols\http\httptools_impl.py
2024-08-31 15:40:27,826 loglevel=INFO   logger=uvicorn.access L489  ::1:57405 - "GET /groups HTTP/1.1" 307 send() call_trace=C:\Users\bharg\AppData\Roaming\Python\Python310\site-packages\uvicorn\protocols\http\httptools_impl.py
2024-08-31 15:40:27,837 loglevel=INFO   logger=uvicorn.access L489  ::1:57405 - "GET /groups/ HTTP/1.1" 200 send() call_trace=C:\Users\bharg\AppData\Roaming\Python\Python310\site-packages\uvicorn\protocols\http\httptools_impl.py
2024-08-31 15:41:09,817 loglevel=INFO   logger=uvicorn.error L265  Shutting down shutdown() call_trace=C:\Users\bharg\AppData\Roaming\Python\Python310\site-packages\uvicorn\server.py
2024-08-31 15:41:09,920 loglevel=INFO   logger=uvicorn.error L65   Waiting for application shutdown. shutdown() call_trace=C:\Users\bharg\AppData\Roaming\Python\Python310\site-packages\uvicorn\lifespan\on.py
2024-08-31 15:41:09,922 loglevel=INFO   logger=uvicorn.error L76   Application shutdown complete. shutdown() call_trace=C:\Users\bharg\AppData\Roaming\Python\Python310\site-packages\uvicorn\lifespan\on.py
2024-08-31 15:41:09,923 loglevel=INFO   logger=uvicorn.error L87   Finished server process [14516] serve() call_trace=C:\Users\bharg\AppData\Roaming\Python\Python310\site-packages\uvicorn\server.py
2024-08-31 15:41:25,276 loglevel=INFO   logger=uvicorn.error L77   Started server process [11324] serve() call_trace=C:\Users\bharg\AppData\Roaming\Python\Python310\site-packages\uvicorn\server.py
2024-08-31 15:41:25,277 loglevel=INFO   logger=uvicorn.error L46   Waiting for application startup. startup() call_trace=C:\Users\bharg\AppData\Roaming\Python\Python310\site-packages\uvicorn\lifespan\on.py
2024-08-31 15:41:25,277 loglevel=INFO   logger=uvicorn.error L60   Application startup complete. startup() call_trace=C:\Users\bharg\AppData\Roaming\Python\Python310\site-packages\uvicorn\lifespan\on.py
2024-08-31 15:41:25,284 loglevel=INFO   logger=uvicorn.error L219  Uvicorn running on http://localhost:8000 (Press CTRL+C to quit) _log_started_message() call_trace=C:\Users\bharg\AppData\Roaming\Python\Python310\site-packages\uvicorn\server.py
2024-08-31 15:41:45,166 loglevel=INFO   logger=uvicorn.access L489  127.0.0.1:57439 - "PUT /groups/7 HTTP/1.1" 200 send() call_trace=C:\Users\bharg\AppData\Roaming\Python\Python310\site-packages\uvicorn\protocols\http\httptools_impl.py
2024-08-31 15:43:05,699 loglevel=INFO   logger=uvicorn.access L489  127.0.0.1:57651 - "PUT /groups/7 HTTP/1.1" 200 send() call_trace=C:\Users\bharg\AppData\Roaming\Python\Python310\site-packages\uvicorn\protocols\http\httptools_impl.py
2024-08-31 15:43:22,776 loglevel=INFO   logger=uvicorn.access L489  127.0.0.1:57690 - "PUT /groups/7 HTTP/1.1" 200 send() call_trace=C:\Users\bharg\AppData\Roaming\Python\Python310\site-packages\uvicorn\protocols\http\httptools_impl.py
2024-08-31 15:46:42,408 loglevel=INFO   logger=uvicorn.access L489  127.0.0.1:57771 - "PUT /groups/7 HTTP/1.1" 200 send() call_trace=C:\Users\bharg\AppData\Roaming\Python\Python310\site-packages\uvicorn\protocols\http\httptools_impl.py
2024-08-31 15:53:45,544 loglevel=INFO   logger=uvicorn.error L265  Shutting down shutdown() call_trace=C:\Users\bharg\AppData\Roaming\Python\Python310\site-packages\uvicorn\server.py
2024-08-31 15:53:45,651 loglevel=INFO   logger=uvicorn.error L65   Waiting for application shutdown. shutdown() call_trace=C:\Users\bharg\AppData\Roaming\Python\Python310\site-packages\uvicorn\lifespan\on.py
2024-08-31 15:53:45,652 loglevel=INFO   logger=uvicorn.error L76   Application shutdown complete. shutdown() call_trace=C:\Users\bharg\AppData\Roaming\Python\Python310\site-packages\uvicorn\lifespan\on.py
2024-08-31 15:53:45,652 loglevel=INFO   logger=uvicorn.error L87   Finished server process [11324] serve() call_trace=C:\Users\bharg\AppData\Roaming\Python\Python310\site-packages\uvicorn\server.py
2024-08-31 15:53:49,498 loglevel=INFO   logger=uvicorn.error L77   Started server process [36548] serve() call_trace=C:\Users\bharg\AppData\Roaming\Python\Python310\site-packages\uvicorn\server.py
2024-08-31 15:53:49,499 loglevel=INFO   logger=uvicorn.error L46   Waiting for application startup. startup() call_trace=C:\Users\bharg\AppData\Roaming\Python\Python310\site-packages\uvicorn\lifespan\on.py
2024-08-31 15:53:49,500 loglevel=INFO   logger=uvicorn.error L60   Application startup complete. startup() call_trace=C:\Users\bharg\AppData\Roaming\Python\Python310\site-packages\uvicorn\lifespan\on.py
2024-08-31 15:53:49,505 loglevel=INFO   logger=uvicorn.error L219  Uvicorn running on http://localhost:8000 (Press CTRL+C to quit) _log_started_message() call_trace=C:\Users\bharg\AppData\Roaming\Python\Python310\site-packages\uvicorn\server.py
2024-08-31 15:53:58,306 loglevel=INFO   logger=uvicorn.access L489  ::1:57915 - "GET /groups HTTP/1.1" 307 send() call_trace=C:\Users\bharg\AppData\Roaming\Python\Python310\site-packages\uvicorn\protocols\http\httptools_impl.py
2024-08-31 15:53:58,379 loglevel=INFO   logger=uvicorn.access L489  ::1:57915 - "GET /groups/ HTTP/1.1" 200 send() call_trace=C:\Users\bharg\AppData\Roaming\Python\Python310\site-packages\uvicorn\protocols\http\httptools_impl.py
2024-08-31 15:54:46,631 loglevel=INFO   logger=uvicorn.access L489  127.0.0.1:57932 - "PUT /groups/3 HTTP/1.1" 500 send() call_trace=C:\Users\bharg\AppData\Roaming\Python\Python310\site-packages\uvicorn\protocols\http\httptools_impl.py
2024-08-31 15:54:46,631 loglevel=ERROR  logger=uvicorn.error L424  Exception in ASGI application
 run_asgi() call_trace=C:\Users\bharg\AppData\Roaming\Python\Python310\site-packages\uvicorn\protocols\http\httptools_impl.py
Traceback (most recent call last):
  File "C:\Users\bharg\AppData\Roaming\Python\Python310\site-packages\uvicorn\protocols\http\httptools_impl.py", line 419, in run_asgi
    result = await app(  # type: ignore[func-returns-value]
  File "C:\Users\bharg\AppData\Roaming\Python\Python310\site-packages\uvicorn\middleware\proxy_headers.py", line 84, in __call__
    return await self.app(scope, receive, send)
  File "C:\Users\bharg\AppData\Roaming\Python\Python310\site-packages\fastapi\applications.py", line 1054, in __call__
    await super().__call__(scope, receive, send)
  File "C:\Users\bharg\AppData\Roaming\Python\Python310\site-packages\starlette\applications.py", line 123, in __call__
    await self.middleware_stack(scope, receive, send)
  File "C:\Users\bharg\AppData\Roaming\Python\Python310\site-packages\starlette\middleware\errors.py", line 186, in __call__
    raise exc
  File "C:\Users\bharg\AppData\Roaming\Python\Python310\site-packages\starlette\middleware\errors.py", line 164, in __call__
    await self.app(scope, receive, _send)
  File "C:\Users\bharg\AppData\Roaming\Python\Python310\site-packages\starlette\middleware\exceptions.py", line 62, in __call__
    await wrap_app_handling_exceptions(self.app, conn)(scope, receive, send)
  File "C:\Users\bharg\AppData\Roaming\Python\Python310\site-packages\starlette\_exception_handler.py", line 64, in wrapped_app
    raise exc
  File "C:\Users\bharg\AppData\Roaming\Python\Python310\site-packages\starlette\_exception_handler.py", line 53, in wrapped_app
    await app(scope, receive, sender)
  File "C:\Users\bharg\AppData\Roaming\Python\Python310\site-packages\starlette\routing.py", line 758, in __call__
    await self.middleware_stack(scope, receive, send)
  File "C:\Users\bharg\AppData\Roaming\Python\Python310\site-packages\starlette\routing.py", line 778, in app
    await route.handle(scope, receive, send)
  File "C:\Users\bharg\AppData\Roaming\Python\Python310\site-packages\starlette\routing.py", line 299, in handle
    await self.app(scope, receive, send)
  File "C:\Users\bharg\AppData\Roaming\Python\Python310\site-packages\starlette\routing.py", line 79, in app
    await wrap_app_handling_exceptions(app, request)(scope, receive, send)
  File "C:\Users\bharg\AppData\Roaming\Python\Python310\site-packages\starlette\_exception_handler.py", line 64, in wrapped_app
    raise exc
  File "C:\Users\bharg\AppData\Roaming\Python\Python310\site-packages\starlette\_exception_handler.py", line 53, in wrapped_app
    await app(scope, receive, sender)
  File "C:\Users\bharg\AppData\Roaming\Python\Python310\site-packages\starlette\routing.py", line 74, in app
    response = await func(request)
  File "C:\Users\bharg\AppData\Roaming\Python\Python310\site-packages\fastapi\routing.py", line 278, in app
    raw_response = await run_endpoint_function(
  File "C:\Users\bharg\AppData\Roaming\Python\Python310\site-packages\fastapi\routing.py", line 193, in run_endpoint_function
    return await run_in_threadpool(dependant.call, **values)
  File "C:\Users\bharg\AppData\Roaming\Python\Python310\site-packages\starlette\concurrency.py", line 42, in run_in_threadpool
    return await anyio.to_thread.run_sync(func, *args)
  File "C:\ProgramData\anaconda3\lib\site-packages\anyio\to_thread.py", line 28, in run_sync
    return await get_asynclib().run_sync_in_worker_thread(func, *args, cancellable=cancellable,
  File "C:\ProgramData\anaconda3\lib\site-packages\anyio\_backends\_asyncio.py", line 818, in run_sync_in_worker_thread
    return await future
  File "C:\ProgramData\anaconda3\lib\site-packages\anyio\_backends\_asyncio.py", line 754, in run
    result = context.run(func, *args)
  File "C:\Git_Repos\splitwise\src\api\routes\groups.py", line 59, in edit_group
    group = session.scalars(stmt).one()
  File "C:\Users\bharg\AppData\Roaming\Python\Python310\site-packages\sqlalchemy\engine\result.py", line 1810, in one
    return self._only_one_row(
  File "C:\Users\bharg\AppData\Roaming\Python\Python310\site-packages\sqlalchemy\engine\result.py", line 752, in _only_one_row
    raise exc.NoResultFound(
sqlalchemy.exc.NoResultFound: No row was found when one was required
2024-08-31 15:58:12,543 loglevel=INFO   logger=uvicorn.access L489  127.0.0.1:58035 - "PUT /groups/4 HTTP/1.1" 200 send() call_trace=C:\Users\bharg\AppData\Roaming\Python\Python310\site-packages\uvicorn\protocols\http\httptools_impl.py
2024-08-31 15:58:26,970 loglevel=INFO   logger=uvicorn.access L489  ::1:58056 - "GET /groups HTTP/1.1" 307 send() call_trace=C:\Users\bharg\AppData\Roaming\Python\Python310\site-packages\uvicorn\protocols\http\httptools_impl.py
2024-08-31 15:58:26,980 loglevel=INFO   logger=uvicorn.access L489  ::1:58056 - "GET /groups/ HTTP/1.1" 200 send() call_trace=C:\Users\bharg\AppData\Roaming\Python\Python310\site-packages\uvicorn\protocols\http\httptools_impl.py
2024-08-31 18:27:33,726 loglevel=INFO   logger=uvicorn.error L265  Shutting down shutdown() call_trace=C:\Users\bharg\AppData\Roaming\Python\Python310\site-packages\uvicorn\server.py
2024-08-31 18:27:33,843 loglevel=INFO   logger=uvicorn.error L65   Waiting for application shutdown. shutdown() call_trace=C:\Users\bharg\AppData\Roaming\Python\Python310\site-packages\uvicorn\lifespan\on.py
2024-08-31 18:27:33,847 loglevel=INFO   logger=uvicorn.error L76   Application shutdown complete. shutdown() call_trace=C:\Users\bharg\AppData\Roaming\Python\Python310\site-packages\uvicorn\lifespan\on.py
2024-08-31 18:27:33,847 loglevel=INFO   logger=uvicorn.error L87   Finished server process [36548] serve() call_trace=C:\Users\bharg\AppData\Roaming\Python\Python310\site-packages\uvicorn\server.py
2024-08-31 21:02:37,781 loglevel=INFO   logger=uvicorn.error L77   Started server process [21276] serve() call_trace=C:\Users\bharg\AppData\Roaming\Python\Python310\site-packages\uvicorn\server.py
2024-08-31 21:02:37,781 loglevel=INFO   logger=uvicorn.error L46   Waiting for application startup. startup() call_trace=C:\Users\bharg\AppData\Roaming\Python\Python310\site-packages\uvicorn\lifespan\on.py
2024-08-31 21:02:37,783 loglevel=INFO   logger=uvicorn.error L60   Application startup complete. startup() call_trace=C:\Users\bharg\AppData\Roaming\Python\Python310\site-packages\uvicorn\lifespan\on.py
2024-08-31 21:02:37,790 loglevel=INFO   logger=uvicorn.error L219  Uvicorn running on http://localhost:8000 (Press CTRL+C to quit) _log_started_message() call_trace=C:\Users\bharg\AppData\Roaming\Python\Python310\site-packages\uvicorn\server.py
2024-08-31 21:16:14,848 loglevel=INFO   logger=uvicorn.error L265  Shutting down shutdown() call_trace=C:\Users\bharg\AppData\Roaming\Python\Python310\site-packages\uvicorn\server.py
2024-08-31 21:16:14,958 loglevel=INFO   logger=uvicorn.error L65   Waiting for application shutdown. shutdown() call_trace=C:\Users\bharg\AppData\Roaming\Python\Python310\site-packages\uvicorn\lifespan\on.py
2024-08-31 21:16:14,959 loglevel=INFO   logger=uvicorn.error L76   Application shutdown complete. shutdown() call_trace=C:\Users\bharg\AppData\Roaming\Python\Python310\site-packages\uvicorn\lifespan\on.py
2024-08-31 21:16:14,959 loglevel=INFO   logger=uvicorn.error L87   Finished server process [21276] serve() call_trace=C:\Users\bharg\AppData\Roaming\Python\Python310\site-packages\uvicorn\server.py
2024-08-31 21:42:43,573 loglevel=INFO   logger=uvicorn.error L77   Started server process [29328] serve() call_trace=C:\Users\bharg\AppData\Roaming\Python\Python310\site-packages\uvicorn\server.py
2024-08-31 21:42:43,574 loglevel=INFO   logger=uvicorn.error L46   Waiting for application startup. startup() call_trace=C:\Users\bharg\AppData\Roaming\Python\Python310\site-packages\uvicorn\lifespan\on.py
2024-08-31 21:42:43,575 loglevel=INFO   logger=uvicorn.error L60   Application startup complete. startup() call_trace=C:\Users\bharg\AppData\Roaming\Python\Python310\site-packages\uvicorn\lifespan\on.py
2024-08-31 21:42:43,579 loglevel=INFO   logger=uvicorn.error L219  Uvicorn running on http://localhost:8000 (Press CTRL+C to quit) _log_started_message() call_trace=C:\Users\bharg\AppData\Roaming\Python\Python310\site-packages\uvicorn\server.py
2024-08-31 21:48:54,603 loglevel=INFO   logger=uvicorn.error L265  Shutting down shutdown() call_trace=C:\Users\bharg\AppData\Roaming\Python\Python310\site-packages\uvicorn\server.py
2024-08-31 21:48:54,715 loglevel=INFO   logger=uvicorn.error L65   Waiting for application shutdown. shutdown() call_trace=C:\Users\bharg\AppData\Roaming\Python\Python310\site-packages\uvicorn\lifespan\on.py
2024-08-31 21:48:54,715 loglevel=INFO   logger=uvicorn.error L76   Application shutdown complete. shutdown() call_trace=C:\Users\bharg\AppData\Roaming\Python\Python310\site-packages\uvicorn\lifespan\on.py
2024-08-31 21:48:54,716 loglevel=INFO   logger=uvicorn.error L87   Finished server process [29328] serve() call_trace=C:\Users\bharg\AppData\Roaming\Python\Python310\site-packages\uvicorn\server.py
2024-08-31 21:48:58,831 loglevel=INFO   logger=uvicorn.error L77   Started server process [19404] serve() call_trace=C:\Users\bharg\AppData\Roaming\Python\Python310\site-packages\uvicorn\server.py
2024-08-31 21:48:58,832 loglevel=INFO   logger=uvicorn.error L46   Waiting for application startup. startup() call_trace=C:\Users\bharg\AppData\Roaming\Python\Python310\site-packages\uvicorn\lifespan\on.py
2024-08-31 21:48:58,832 loglevel=INFO   logger=uvicorn.error L60   Application startup complete. startup() call_trace=C:\Users\bharg\AppData\Roaming\Python\Python310\site-packages\uvicorn\lifespan\on.py
2024-08-31 21:48:58,838 loglevel=INFO   logger=uvicorn.error L219  Uvicorn running on http://localhost:8000 (Press CTRL+C to quit) _log_started_message() call_trace=C:\Users\bharg\AppData\Roaming\Python\Python310\site-packages\uvicorn\server.py
2024-08-31 21:54:37,829 loglevel=INFO   logger=uvicorn.access L489  127.0.0.1:64009 - "POST /expenses/ HTTP/1.1" 422 send() call_trace=C:\Users\bharg\AppData\Roaming\Python\Python310\site-packages\uvicorn\protocols\http\httptools_impl.py
2024-08-31 21:56:20,872 loglevel=INFO   logger=uvicorn.access L489  127.0.0.1:64071 - "POST /expenses/ HTTP/1.1" 422 send() call_trace=C:\Users\bharg\AppData\Roaming\Python\Python310\site-packages\uvicorn\protocols\http\httptools_impl.py
2024-08-31 21:57:06,999 loglevel=INFO   logger=uvicorn.access L489  127.0.0.1:64150 - "POST /expenses/ HTTP/1.1" 500 send() call_trace=C:\Users\bharg\AppData\Roaming\Python\Python310\site-packages\uvicorn\protocols\http\httptools_impl.py
2024-08-31 21:57:07,000 loglevel=ERROR  logger=uvicorn.error L424  Exception in ASGI application
 run_asgi() call_trace=C:\Users\bharg\AppData\Roaming\Python\Python310\site-packages\uvicorn\protocols\http\httptools_impl.py
Traceback (most recent call last):
  File "C:\Users\bharg\AppData\Roaming\Python\Python310\site-packages\uvicorn\protocols\http\httptools_impl.py", line 419, in run_asgi
    result = await app(  # type: ignore[func-returns-value]
  File "C:\Users\bharg\AppData\Roaming\Python\Python310\site-packages\uvicorn\middleware\proxy_headers.py", line 84, in __call__
    return await self.app(scope, receive, send)
  File "C:\Users\bharg\AppData\Roaming\Python\Python310\site-packages\fastapi\applications.py", line 1054, in __call__
    await super().__call__(scope, receive, send)
  File "C:\Users\bharg\AppData\Roaming\Python\Python310\site-packages\starlette\applications.py", line 123, in __call__
    await self.middleware_stack(scope, receive, send)
  File "C:\Users\bharg\AppData\Roaming\Python\Python310\site-packages\starlette\middleware\errors.py", line 186, in __call__
    raise exc
  File "C:\Users\bharg\AppData\Roaming\Python\Python310\site-packages\starlette\middleware\errors.py", line 164, in __call__
    await self.app(scope, receive, _send)
  File "C:\Users\bharg\AppData\Roaming\Python\Python310\site-packages\starlette\middleware\exceptions.py", line 62, in __call__
    await wrap_app_handling_exceptions(self.app, conn)(scope, receive, send)
  File "C:\Users\bharg\AppData\Roaming\Python\Python310\site-packages\starlette\_exception_handler.py", line 64, in wrapped_app
    raise exc
  File "C:\Users\bharg\AppData\Roaming\Python\Python310\site-packages\starlette\_exception_handler.py", line 53, in wrapped_app
    await app(scope, receive, sender)
  File "C:\Users\bharg\AppData\Roaming\Python\Python310\site-packages\starlette\routing.py", line 758, in __call__
    await self.middleware_stack(scope, receive, send)
  File "C:\Users\bharg\AppData\Roaming\Python\Python310\site-packages\starlette\routing.py", line 778, in app
    await route.handle(scope, receive, send)
  File "C:\Users\bharg\AppData\Roaming\Python\Python310\site-packages\starlette\routing.py", line 299, in handle
    await self.app(scope, receive, send)
  File "C:\Users\bharg\AppData\Roaming\Python\Python310\site-packages\starlette\routing.py", line 79, in app
    await wrap_app_handling_exceptions(app, request)(scope, receive, send)
  File "C:\Users\bharg\AppData\Roaming\Python\Python310\site-packages\starlette\_exception_handler.py", line 64, in wrapped_app
    raise exc
  File "C:\Users\bharg\AppData\Roaming\Python\Python310\site-packages\starlette\_exception_handler.py", line 53, in wrapped_app
    await app(scope, receive, sender)
  File "C:\Users\bharg\AppData\Roaming\Python\Python310\site-packages\starlette\routing.py", line 74, in app
    response = await func(request)
  File "C:\Users\bharg\AppData\Roaming\Python\Python310\site-packages\fastapi\routing.py", line 278, in app
    raw_response = await run_endpoint_function(
  File "C:\Users\bharg\AppData\Roaming\Python\Python310\site-packages\fastapi\routing.py", line 193, in run_endpoint_function
    return await run_in_threadpool(dependant.call, **values)
  File "C:\Users\bharg\AppData\Roaming\Python\Python310\site-packages\starlette\concurrency.py", line 42, in run_in_threadpool
    return await anyio.to_thread.run_sync(func, *args)
  File "C:\ProgramData\anaconda3\lib\site-packages\anyio\to_thread.py", line 28, in run_sync
    return await get_asynclib().run_sync_in_worker_thread(func, *args, cancellable=cancellable,
  File "C:\ProgramData\anaconda3\lib\site-packages\anyio\_backends\_asyncio.py", line 818, in run_sync_in_worker_thread
    return await future
  File "C:\ProgramData\anaconda3\lib\site-packages\anyio\_backends\_asyncio.py", line 754, in run
    result = context.run(func, *args)
  File "C:\Git_Repos\splitwise\src\api\routes\expenses.py", line 54, in create_expense
    simplified_map = get_simplified_map(request.expense_breakdowns)
  File "C:\Users\bharg\AppData\Roaming\Python\Python310\site-packages\pydantic\main.py", line 767, in __getattr__
    raise AttributeError(f'{type(self).__name__!r} object has no attribute {item!r}')
AttributeError: 'ExpenseCreateRequest' object has no attribute 'expense_breakdowns'
2024-08-31 21:57:44,687 loglevel=INFO   logger=uvicorn.error L265  Shutting down shutdown() call_trace=C:\Users\bharg\AppData\Roaming\Python\Python310\site-packages\uvicorn\server.py
2024-08-31 21:57:44,797 loglevel=INFO   logger=uvicorn.error L65   Waiting for application shutdown. shutdown() call_trace=C:\Users\bharg\AppData\Roaming\Python\Python310\site-packages\uvicorn\lifespan\on.py
2024-08-31 21:57:44,797 loglevel=INFO   logger=uvicorn.error L76   Application shutdown complete. shutdown() call_trace=C:\Users\bharg\AppData\Roaming\Python\Python310\site-packages\uvicorn\lifespan\on.py
2024-08-31 21:57:44,798 loglevel=INFO   logger=uvicorn.error L87   Finished server process [19404] serve() call_trace=C:\Users\bharg\AppData\Roaming\Python\Python310\site-packages\uvicorn\server.py
2024-08-31 21:57:48,533 loglevel=INFO   logger=uvicorn.error L77   Started server process [17920] serve() call_trace=C:\Users\bharg\AppData\Roaming\Python\Python310\site-packages\uvicorn\server.py
2024-08-31 21:57:48,533 loglevel=INFO   logger=uvicorn.error L46   Waiting for application startup. startup() call_trace=C:\Users\bharg\AppData\Roaming\Python\Python310\site-packages\uvicorn\lifespan\on.py
2024-08-31 21:57:48,534 loglevel=INFO   logger=uvicorn.error L60   Application startup complete. startup() call_trace=C:\Users\bharg\AppData\Roaming\Python\Python310\site-packages\uvicorn\lifespan\on.py
2024-08-31 21:57:48,541 loglevel=INFO   logger=uvicorn.error L219  Uvicorn running on http://localhost:8000 (Press CTRL+C to quit) _log_started_message() call_trace=C:\Users\bharg\AppData\Roaming\Python\Python310\site-packages\uvicorn\server.py
2024-08-31 21:57:57,407 loglevel=INFO   logger=uvicorn.access L489  127.0.0.1:64180 - "POST /expenses/ HTTP/1.1" 500 send() call_trace=C:\Users\bharg\AppData\Roaming\Python\Python310\site-packages\uvicorn\protocols\http\httptools_impl.py
2024-08-31 21:57:57,408 loglevel=ERROR  logger=uvicorn.error L424  Exception in ASGI application
 run_asgi() call_trace=C:\Users\bharg\AppData\Roaming\Python\Python310\site-packages\uvicorn\protocols\http\httptools_impl.py
Traceback (most recent call last):
  File "C:\Users\bharg\AppData\Roaming\Python\Python310\site-packages\uvicorn\protocols\http\httptools_impl.py", line 419, in run_asgi
    result = await app(  # type: ignore[func-returns-value]
  File "C:\Users\bharg\AppData\Roaming\Python\Python310\site-packages\uvicorn\middleware\proxy_headers.py", line 84, in __call__
    return await self.app(scope, receive, send)
  File "C:\Users\bharg\AppData\Roaming\Python\Python310\site-packages\fastapi\applications.py", line 1054, in __call__
    await super().__call__(scope, receive, send)
  File "C:\Users\bharg\AppData\Roaming\Python\Python310\site-packages\starlette\applications.py", line 123, in __call__
    await self.middleware_stack(scope, receive, send)
  File "C:\Users\bharg\AppData\Roaming\Python\Python310\site-packages\starlette\middleware\errors.py", line 186, in __call__
    raise exc
  File "C:\Users\bharg\AppData\Roaming\Python\Python310\site-packages\starlette\middleware\errors.py", line 164, in __call__
    await self.app(scope, receive, _send)
  File "C:\Users\bharg\AppData\Roaming\Python\Python310\site-packages\starlette\middleware\exceptions.py", line 62, in __call__
    await wrap_app_handling_exceptions(self.app, conn)(scope, receive, send)
  File "C:\Users\bharg\AppData\Roaming\Python\Python310\site-packages\starlette\_exception_handler.py", line 64, in wrapped_app
    raise exc
  File "C:\Users\bharg\AppData\Roaming\Python\Python310\site-packages\starlette\_exception_handler.py", line 53, in wrapped_app
    await app(scope, receive, sender)
  File "C:\Users\bharg\AppData\Roaming\Python\Python310\site-packages\starlette\routing.py", line 758, in __call__
    await self.middleware_stack(scope, receive, send)
  File "C:\Users\bharg\AppData\Roaming\Python\Python310\site-packages\starlette\routing.py", line 778, in app
    await route.handle(scope, receive, send)
  File "C:\Users\bharg\AppData\Roaming\Python\Python310\site-packages\starlette\routing.py", line 299, in handle
    await self.app(scope, receive, send)
  File "C:\Users\bharg\AppData\Roaming\Python\Python310\site-packages\starlette\routing.py", line 79, in app
    await wrap_app_handling_exceptions(app, request)(scope, receive, send)
  File "C:\Users\bharg\AppData\Roaming\Python\Python310\site-packages\starlette\_exception_handler.py", line 64, in wrapped_app
    raise exc
  File "C:\Users\bharg\AppData\Roaming\Python\Python310\site-packages\starlette\_exception_handler.py", line 53, in wrapped_app
    await app(scope, receive, sender)
  File "C:\Users\bharg\AppData\Roaming\Python\Python310\site-packages\starlette\routing.py", line 74, in app
    response = await func(request)
  File "C:\Users\bharg\AppData\Roaming\Python\Python310\site-packages\fastapi\routing.py", line 278, in app
    raw_response = await run_endpoint_function(
  File "C:\Users\bharg\AppData\Roaming\Python\Python310\site-packages\fastapi\routing.py", line 193, in run_endpoint_function
    return await run_in_threadpool(dependant.call, **values)
  File "C:\Users\bharg\AppData\Roaming\Python\Python310\site-packages\starlette\concurrency.py", line 42, in run_in_threadpool
    return await anyio.to_thread.run_sync(func, *args)
  File "C:\ProgramData\anaconda3\lib\site-packages\anyio\to_thread.py", line 28, in run_sync
    return await get_asynclib().run_sync_in_worker_thread(func, *args, cancellable=cancellable,
  File "C:\ProgramData\anaconda3\lib\site-packages\anyio\_backends\_asyncio.py", line 818, in run_sync_in_worker_thread
    return await future
  File "C:\ProgramData\anaconda3\lib\site-packages\anyio\_backends\_asyncio.py", line 754, in run
    result = context.run(func, *args)
  File "C:\Git_Repos\splitwise\src\api\routes\expenses.py", line 56, in create_expense
    expense_breakdowns = [ ExpenseBreakDown(payer=payer, reciever=reciever, amount=amount)  for payer, reciever, amount in transaction_tuples ]
  File "C:\Git_Repos\splitwise\src\api\routes\expenses.py", line 56, in <listcomp>
    expense_breakdowns = [ ExpenseBreakDown(payer=payer, reciever=reciever, amount=amount)  for payer, reciever, amount in transaction_tuples ]
  File "<string>", line 4, in __init__
  File "C:\Users\bharg\AppData\Roaming\Python\Python310\site-packages\sqlalchemy\orm\state.py", line 564, in _initialize_instance
    with util.safe_reraise():
  File "C:\Users\bharg\AppData\Roaming\Python\Python310\site-packages\sqlalchemy\util\langhelpers.py", line 146, in __exit__
    raise exc_value.with_traceback(exc_tb)
  File "C:\Users\bharg\AppData\Roaming\Python\Python310\site-packages\sqlalchemy\orm\state.py", line 562, in _initialize_instance
    manager.original_init(*mixed[1:], **kwargs)
  File "C:\Users\bharg\AppData\Roaming\Python\Python310\site-packages\sqlalchemy\orm\decl_base.py", line 2139, in _declarative_constructor
    raise TypeError(
TypeError: 'payer' is an invalid keyword argument for ExpenseBreakDown
2024-08-31 21:58:53,558 loglevel=INFO   logger=uvicorn.error L265  Shutting down shutdown() call_trace=C:\Users\bharg\AppData\Roaming\Python\Python310\site-packages\uvicorn\server.py
2024-08-31 21:58:53,668 loglevel=INFO   logger=uvicorn.error L65   Waiting for application shutdown. shutdown() call_trace=C:\Users\bharg\AppData\Roaming\Python\Python310\site-packages\uvicorn\lifespan\on.py
2024-08-31 21:58:53,669 loglevel=INFO   logger=uvicorn.error L76   Application shutdown complete. shutdown() call_trace=C:\Users\bharg\AppData\Roaming\Python\Python310\site-packages\uvicorn\lifespan\on.py
2024-08-31 21:58:53,669 loglevel=INFO   logger=uvicorn.error L87   Finished server process [17920] serve() call_trace=C:\Users\bharg\AppData\Roaming\Python\Python310\site-packages\uvicorn\server.py
2024-08-31 21:59:00,200 loglevel=INFO   logger=uvicorn.error L77   Started server process [18108] serve() call_trace=C:\Users\bharg\AppData\Roaming\Python\Python310\site-packages\uvicorn\server.py
2024-08-31 21:59:00,201 loglevel=INFO   logger=uvicorn.error L46   Waiting for application startup. startup() call_trace=C:\Users\bharg\AppData\Roaming\Python\Python310\site-packages\uvicorn\lifespan\on.py
2024-08-31 21:59:00,202 loglevel=INFO   logger=uvicorn.error L60   Application startup complete. startup() call_trace=C:\Users\bharg\AppData\Roaming\Python\Python310\site-packages\uvicorn\lifespan\on.py
2024-08-31 21:59:00,207 loglevel=INFO   logger=uvicorn.error L219  Uvicorn running on http://localhost:8000 (Press CTRL+C to quit) _log_started_message() call_trace=C:\Users\bharg\AppData\Roaming\Python\Python310\site-packages\uvicorn\server.py
2024-08-31 21:59:34,427 loglevel=INFO   logger=uvicorn.access L489  127.0.0.1:64245 - "POST /expenses/ HTTP/1.1" 500 send() call_trace=C:\Users\bharg\AppData\Roaming\Python\Python310\site-packages\uvicorn\protocols\http\httptools_impl.py
2024-08-31 21:59:34,428 loglevel=ERROR  logger=uvicorn.error L424  Exception in ASGI application
 run_asgi() call_trace=C:\Users\bharg\AppData\Roaming\Python\Python310\site-packages\uvicorn\protocols\http\httptools_impl.py
Traceback (most recent call last):
  File "C:\Users\bharg\AppData\Roaming\Python\Python310\site-packages\sqlalchemy\engine\base.py", line 2116, in _exec_insertmany_context
    dialect.do_execute(
  File "C:\Users\bharg\AppData\Roaming\Python\Python310\site-packages\sqlalchemy\engine\default.py", line 924, in do_execute
    cursor.execute(statement, parameters)
psycopg2.errors.ForeignKeyViolation: insert or update on table "expense_breakdowns" violates foreign key constraint "expense_breakdowns_receiver_id_fkey"
DETAIL:  Key (receiver_id)=(3) is not present in table "users".


The above exception was the direct cause of the following exception:

Traceback (most recent call last):
  File "C:\Users\bharg\AppData\Roaming\Python\Python310\site-packages\uvicorn\protocols\http\httptools_impl.py", line 419, in run_asgi
    result = await app(  # type: ignore[func-returns-value]
  File "C:\Users\bharg\AppData\Roaming\Python\Python310\site-packages\uvicorn\middleware\proxy_headers.py", line 84, in __call__
    return await self.app(scope, receive, send)
  File "C:\Users\bharg\AppData\Roaming\Python\Python310\site-packages\fastapi\applications.py", line 1054, in __call__
    await super().__call__(scope, receive, send)
  File "C:\Users\bharg\AppData\Roaming\Python\Python310\site-packages\starlette\applications.py", line 123, in __call__
    await self.middleware_stack(scope, receive, send)
  File "C:\Users\bharg\AppData\Roaming\Python\Python310\site-packages\starlette\middleware\errors.py", line 186, in __call__
    raise exc
  File "C:\Users\bharg\AppData\Roaming\Python\Python310\site-packages\starlette\middleware\errors.py", line 164, in __call__
    await self.app(scope, receive, _send)
  File "C:\Users\bharg\AppData\Roaming\Python\Python310\site-packages\starlette\middleware\exceptions.py", line 62, in __call__
    await wrap_app_handling_exceptions(self.app, conn)(scope, receive, send)
  File "C:\Users\bharg\AppData\Roaming\Python\Python310\site-packages\starlette\_exception_handler.py", line 64, in wrapped_app
    raise exc
  File "C:\Users\bharg\AppData\Roaming\Python\Python310\site-packages\starlette\_exception_handler.py", line 53, in wrapped_app
    await app(scope, receive, sender)
  File "C:\Users\bharg\AppData\Roaming\Python\Python310\site-packages\starlette\routing.py", line 758, in __call__
    await self.middleware_stack(scope, receive, send)
  File "C:\Users\bharg\AppData\Roaming\Python\Python310\site-packages\starlette\routing.py", line 778, in app
    await route.handle(scope, receive, send)
  File "C:\Users\bharg\AppData\Roaming\Python\Python310\site-packages\starlette\routing.py", line 299, in handle
    await self.app(scope, receive, send)
  File "C:\Users\bharg\AppData\Roaming\Python\Python310\site-packages\starlette\routing.py", line 79, in app
    await wrap_app_handling_exceptions(app, request)(scope, receive, send)
  File "C:\Users\bharg\AppData\Roaming\Python\Python310\site-packages\starlette\_exception_handler.py", line 64, in wrapped_app
    raise exc
  File "C:\Users\bharg\AppData\Roaming\Python\Python310\site-packages\starlette\_exception_handler.py", line 53, in wrapped_app
    await app(scope, receive, sender)
  File "C:\Users\bharg\AppData\Roaming\Python\Python310\site-packages\starlette\routing.py", line 74, in app
    response = await func(request)
  File "C:\Users\bharg\AppData\Roaming\Python\Python310\site-packages\fastapi\routing.py", line 278, in app
    raw_response = await run_endpoint_function(
  File "C:\Users\bharg\AppData\Roaming\Python\Python310\site-packages\fastapi\routing.py", line 193, in run_endpoint_function
    return await run_in_threadpool(dependant.call, **values)
  File "C:\Users\bharg\AppData\Roaming\Python\Python310\site-packages\starlette\concurrency.py", line 42, in run_in_threadpool
    return await anyio.to_thread.run_sync(func, *args)
  File "C:\ProgramData\anaconda3\lib\site-packages\anyio\to_thread.py", line 28, in run_sync
    return await get_asynclib().run_sync_in_worker_thread(func, *args, cancellable=cancellable,
  File "C:\ProgramData\anaconda3\lib\site-packages\anyio\_backends\_asyncio.py", line 818, in run_sync_in_worker_thread
    return await future
  File "C:\ProgramData\anaconda3\lib\site-packages\anyio\_backends\_asyncio.py", line 754, in run
    result = context.run(func, *args)
  File "C:\Git_Repos\splitwise\src\api\routes\expenses.py", line 60, in create_expense
    session.commit()
  File "C:\Users\bharg\AppData\Roaming\Python\Python310\site-packages\sqlalchemy\orm\session.py", line 2017, in commit
    trans.commit(_to_root=True)
  File "<string>", line 2, in commit
  File "C:\Users\bharg\AppData\Roaming\Python\Python310\site-packages\sqlalchemy\orm\state_changes.py", line 139, in _go
    ret_value = fn(self, *arg, **kw)
  File "C:\Users\bharg\AppData\Roaming\Python\Python310\site-packages\sqlalchemy\orm\session.py", line 1302, in commit
    self._prepare_impl()
  File "<string>", line 2, in _prepare_impl
  File "C:\Users\bharg\AppData\Roaming\Python\Python310\site-packages\sqlalchemy\orm\state_changes.py", line 139, in _go
    ret_value = fn(self, *arg, **kw)
  File "C:\Users\bharg\AppData\Roaming\Python\Python310\site-packages\sqlalchemy\orm\session.py", line 1277, in _prepare_impl
    self.session.flush()
  File "C:\Users\bharg\AppData\Roaming\Python\Python310\site-packages\sqlalchemy\orm\session.py", line 4341, in flush
    self._flush(objects)
  File "C:\Users\bharg\AppData\Roaming\Python\Python310\site-packages\sqlalchemy\orm\session.py", line 4476, in _flush
    with util.safe_reraise():
  File "C:\Users\bharg\AppData\Roaming\Python\Python310\site-packages\sqlalchemy\util\langhelpers.py", line 146, in __exit__
    raise exc_value.with_traceback(exc_tb)
  File "C:\Users\bharg\AppData\Roaming\Python\Python310\site-packages\sqlalchemy\orm\session.py", line 4437, in _flush
    flush_context.execute()
  File "C:\Users\bharg\AppData\Roaming\Python\Python310\site-packages\sqlalchemy\orm\unitofwork.py", line 466, in execute
    rec.execute(self)
  File "C:\Users\bharg\AppData\Roaming\Python\Python310\site-packages\sqlalchemy\orm\unitofwork.py", line 642, in execute
    util.preloaded.orm_persistence.save_obj(
  File "C:\Users\bharg\AppData\Roaming\Python\Python310\site-packages\sqlalchemy\orm\persistence.py", line 93, in save_obj
    _emit_insert_statements(
  File "C:\Users\bharg\AppData\Roaming\Python\Python310\site-packages\sqlalchemy\orm\persistence.py", line 1143, in _emit_insert_statements
    result = connection.execute(
  File "C:\Users\bharg\AppData\Roaming\Python\Python310\site-packages\sqlalchemy\engine\base.py", line 1418, in execute
    return meth(
  File "C:\Users\bharg\AppData\Roaming\Python\Python310\site-packages\sqlalchemy\sql\elements.py", line 515, in _execute_on_connection
    return connection._execute_clauseelement(
  File "C:\Users\bharg\AppData\Roaming\Python\Python310\site-packages\sqlalchemy\engine\base.py", line 1640, in _execute_clauseelement
    ret = self._execute_context(
  File "C:\Users\bharg\AppData\Roaming\Python\Python310\site-packages\sqlalchemy\engine\base.py", line 1844, in _execute_context
    return self._exec_insertmany_context(dialect, context)
  File "C:\Users\bharg\AppData\Roaming\Python\Python310\site-packages\sqlalchemy\engine\base.py", line 2124, in _exec_insertmany_context
    self._handle_dbapi_exception(
  File "C:\Users\bharg\AppData\Roaming\Python\Python310\site-packages\sqlalchemy\engine\base.py", line 2353, in _handle_dbapi_exception
    raise sqlalchemy_exception.with_traceback(exc_info[2]) from e
  File "C:\Users\bharg\AppData\Roaming\Python\Python310\site-packages\sqlalchemy\engine\base.py", line 2116, in _exec_insertmany_context
    dialect.do_execute(
  File "C:\Users\bharg\AppData\Roaming\Python\Python310\site-packages\sqlalchemy\engine\default.py", line 924, in do_execute
    cursor.execute(statement, parameters)
sqlalchemy.exc.IntegrityError: (psycopg2.errors.ForeignKeyViolation) insert or update on table "expense_breakdowns" violates foreign key constraint "expense_breakdowns_receiver_id_fkey"
DETAIL:  Key (receiver_id)=(3) is not present in table "users".

[SQL: INSERT INTO expense_breakdowns (expense_id, payer_id, receiver_id, amount, is_settled) SELECT p0::INTEGER, p1::INTEGER, p2::INTEGER, p3::INTEGER, p4::BOOLEAN FROM (VALUES (%(expense_id__0)s, %(payer_id__0)s, %(receiver_id__0)s, %(amount__0)s, %(is_settled__0)s, 0), (%(expense_id__1)s, %(payer_id__1)s, %(receiver_id__1)s, %(amount__1)s, %(is_settled__1)s, 1)) AS imp_sen(p0, p1, p2, p3, p4, sen_counter) ORDER BY sen_counter RETURNING expense_breakdowns.id, expense_breakdowns.id AS id__1]
[parameters: {'receiver_id__0': 3, 'is_settled__0': False, 'amount__0': 20, 'expense_id__0': 1, 'payer_id__0': 1, 'receiver_id__1': 3, 'is_settled__1': False, 'amount__1': 10, 'expense_id__1': 1, 'payer_id__1': 2}]
(Background on this error at: https://sqlalche.me/e/20/gkpj)
2024-08-31 22:10:11,912 loglevel=INFO   logger=uvicorn.access L489  ::1:64513 - "GET /groups HTTP/1.1" 307 send() call_trace=C:\Users\bharg\AppData\Roaming\Python\Python310\site-packages\uvicorn\protocols\http\httptools_impl.py
2024-08-31 22:10:11,939 loglevel=INFO   logger=uvicorn.access L489  ::1:64513 - "GET /groups/ HTTP/1.1" 200 send() call_trace=C:\Users\bharg\AppData\Roaming\Python\Python310\site-packages\uvicorn\protocols\http\httptools_impl.py
2024-08-31 22:10:43,700 loglevel=INFO   logger=uvicorn.access L489  127.0.0.1:64535 - "PUT /groups/5 HTTP/1.1" 200 send() call_trace=C:\Users\bharg\AppData\Roaming\Python\Python310\site-packages\uvicorn\protocols\http\httptools_impl.py
2024-08-31 22:10:49,667 loglevel=INFO   logger=uvicorn.access L489  ::1:64538 - "GET /groups HTTP/1.1" 307 send() call_trace=C:\Users\bharg\AppData\Roaming\Python\Python310\site-packages\uvicorn\protocols\http\httptools_impl.py
2024-08-31 22:10:49,696 loglevel=INFO   logger=uvicorn.access L489  ::1:64538 - "GET /groups/ HTTP/1.1" 200 send() call_trace=C:\Users\bharg\AppData\Roaming\Python\Python310\site-packages\uvicorn\protocols\http\httptools_impl.py
2024-08-31 22:11:12,914 loglevel=INFO   logger=uvicorn.access L489  127.0.0.1:64543 - "POST /expenses/ HTTP/1.1" 200 send() call_trace=C:\Users\bharg\AppData\Roaming\Python\Python310\site-packages\uvicorn\protocols\http\httptools_impl.py
2024-08-31 22:13:12,412 loglevel=INFO   logger=uvicorn.access L489  127.0.0.1:64847 - "POST /expenses/ HTTP/1.1" 200 send() call_trace=C:\Users\bharg\AppData\Roaming\Python\Python310\site-packages\uvicorn\protocols\http\httptools_impl.py
2024-08-31 22:28:51,302 loglevel=INFO   logger=uvicorn.access L489  127.0.0.1:50442 - "DELETE /expenses/3 HTTP/1.1" 404 send() call_trace=C:\Users\bharg\AppData\Roaming\Python\Python310\site-packages\uvicorn\protocols\http\httptools_impl.py
2024-08-31 22:29:05,970 loglevel=INFO   logger=uvicorn.error L265  Shutting down shutdown() call_trace=C:\Users\bharg\AppData\Roaming\Python\Python310\site-packages\uvicorn\server.py
2024-08-31 22:29:06,079 loglevel=INFO   logger=uvicorn.error L65   Waiting for application shutdown. shutdown() call_trace=C:\Users\bharg\AppData\Roaming\Python\Python310\site-packages\uvicorn\lifespan\on.py
2024-08-31 22:29:06,081 loglevel=INFO   logger=uvicorn.error L76   Application shutdown complete. shutdown() call_trace=C:\Users\bharg\AppData\Roaming\Python\Python310\site-packages\uvicorn\lifespan\on.py
2024-08-31 22:29:06,083 loglevel=INFO   logger=uvicorn.error L87   Finished server process [18108] serve() call_trace=C:\Users\bharg\AppData\Roaming\Python\Python310\site-packages\uvicorn\server.py
2024-08-31 22:29:09,332 loglevel=INFO   logger=uvicorn.error L77   Started server process [34316] serve() call_trace=C:\Users\bharg\AppData\Roaming\Python\Python310\site-packages\uvicorn\server.py
2024-08-31 22:29:09,332 loglevel=INFO   logger=uvicorn.error L46   Waiting for application startup. startup() call_trace=C:\Users\bharg\AppData\Roaming\Python\Python310\site-packages\uvicorn\lifespan\on.py
2024-08-31 22:29:09,333 loglevel=INFO   logger=uvicorn.error L60   Application startup complete. startup() call_trace=C:\Users\bharg\AppData\Roaming\Python\Python310\site-packages\uvicorn\lifespan\on.py
2024-08-31 22:29:09,337 loglevel=INFO   logger=uvicorn.error L219  Uvicorn running on http://localhost:8000 (Press CTRL+C to quit) _log_started_message() call_trace=C:\Users\bharg\AppData\Roaming\Python\Python310\site-packages\uvicorn\server.py
2024-08-31 22:31:06,228 loglevel=INFO   logger=uvicorn.access L489  127.0.0.1:50478 - "DELETE /expenses/3 HTTP/1.1" 500 send() call_trace=C:\Users\bharg\AppData\Roaming\Python\Python310\site-packages\uvicorn\protocols\http\httptools_impl.py
2024-08-31 22:31:06,228 loglevel=ERROR  logger=uvicorn.error L424  Exception in ASGI application
 run_asgi() call_trace=C:\Users\bharg\AppData\Roaming\Python\Python310\site-packages\uvicorn\protocols\http\httptools_impl.py
Traceback (most recent call last):
  File "C:\Users\bharg\AppData\Roaming\Python\Python310\site-packages\sqlalchemy\engine\base.py", line 1967, in _exec_single_context
    self.dialect.do_execute(
  File "C:\Users\bharg\AppData\Roaming\Python\Python310\site-packages\sqlalchemy\engine\default.py", line 924, in do_execute
    cursor.execute(statement, parameters)
psycopg2.errors.UndefinedColumn: column expenses.group_id does not exist
LINE 1: SELECT expenses.id, expenses.creator_id, expenses.group_id, ...
                                                 ^


The above exception was the direct cause of the following exception:

Traceback (most recent call last):
  File "C:\Users\bharg\AppData\Roaming\Python\Python310\site-packages\uvicorn\protocols\http\httptools_impl.py", line 419, in run_asgi
    result = await app(  # type: ignore[func-returns-value]
  File "C:\Users\bharg\AppData\Roaming\Python\Python310\site-packages\uvicorn\middleware\proxy_headers.py", line 84, in __call__
    return await self.app(scope, receive, send)
  File "C:\Users\bharg\AppData\Roaming\Python\Python310\site-packages\fastapi\applications.py", line 1054, in __call__
    await super().__call__(scope, receive, send)
  File "C:\Users\bharg\AppData\Roaming\Python\Python310\site-packages\starlette\applications.py", line 123, in __call__
    await self.middleware_stack(scope, receive, send)
  File "C:\Users\bharg\AppData\Roaming\Python\Python310\site-packages\starlette\middleware\errors.py", line 186, in __call__
    raise exc
  File "C:\Users\bharg\AppData\Roaming\Python\Python310\site-packages\starlette\middleware\errors.py", line 164, in __call__
    await self.app(scope, receive, _send)
  File "C:\Users\bharg\AppData\Roaming\Python\Python310\site-packages\starlette\middleware\exceptions.py", line 62, in __call__
    await wrap_app_handling_exceptions(self.app, conn)(scope, receive, send)
  File "C:\Users\bharg\AppData\Roaming\Python\Python310\site-packages\starlette\_exception_handler.py", line 64, in wrapped_app
    raise exc
  File "C:\Users\bharg\AppData\Roaming\Python\Python310\site-packages\starlette\_exception_handler.py", line 53, in wrapped_app
    await app(scope, receive, sender)
  File "C:\Users\bharg\AppData\Roaming\Python\Python310\site-packages\starlette\routing.py", line 758, in __call__
    await self.middleware_stack(scope, receive, send)
  File "C:\Users\bharg\AppData\Roaming\Python\Python310\site-packages\starlette\routing.py", line 778, in app
    await route.handle(scope, receive, send)
  File "C:\Users\bharg\AppData\Roaming\Python\Python310\site-packages\starlette\routing.py", line 299, in handle
    await self.app(scope, receive, send)
  File "C:\Users\bharg\AppData\Roaming\Python\Python310\site-packages\starlette\routing.py", line 79, in app
    await wrap_app_handling_exceptions(app, request)(scope, receive, send)
  File "C:\Users\bharg\AppData\Roaming\Python\Python310\site-packages\starlette\_exception_handler.py", line 64, in wrapped_app
    raise exc
  File "C:\Users\bharg\AppData\Roaming\Python\Python310\site-packages\starlette\_exception_handler.py", line 53, in wrapped_app
    await app(scope, receive, sender)
  File "C:\Users\bharg\AppData\Roaming\Python\Python310\site-packages\starlette\routing.py", line 74, in app
    response = await func(request)
  File "C:\Users\bharg\AppData\Roaming\Python\Python310\site-packages\fastapi\routing.py", line 278, in app
    raw_response = await run_endpoint_function(
  File "C:\Users\bharg\AppData\Roaming\Python\Python310\site-packages\fastapi\routing.py", line 193, in run_endpoint_function
    return await run_in_threadpool(dependant.call, **values)
  File "C:\Users\bharg\AppData\Roaming\Python\Python310\site-packages\starlette\concurrency.py", line 42, in run_in_threadpool
    return await anyio.to_thread.run_sync(func, *args)
  File "C:\ProgramData\anaconda3\lib\site-packages\anyio\to_thread.py", line 28, in run_sync
    return await get_asynclib().run_sync_in_worker_thread(func, *args, cancellable=cancellable,
  File "C:\ProgramData\anaconda3\lib\site-packages\anyio\_backends\_asyncio.py", line 818, in run_sync_in_worker_thread
    return await future
  File "C:\ProgramData\anaconda3\lib\site-packages\anyio\_backends\_asyncio.py", line 754, in run
    result = context.run(func, *args)
  File "C:\Git_Repos\splitwise\src\api\routes\expenses.py", line 68, in delete_group
    expense = session.scalars(stmt).one()
  File "C:\Users\bharg\AppData\Roaming\Python\Python310\site-packages\sqlalchemy\orm\session.py", line 2459, in scalars
    return self._execute_internal(
  File "C:\Users\bharg\AppData\Roaming\Python\Python310\site-packages\sqlalchemy\orm\session.py", line 2236, in _execute_internal
    result: Result[Any] = compile_state_cls.orm_execute_statement(
  File "C:\Users\bharg\AppData\Roaming\Python\Python310\site-packages\sqlalchemy\orm\context.py", line 293, in orm_execute_statement
    result = conn.execute(
  File "C:\Users\bharg\AppData\Roaming\Python\Python310\site-packages\sqlalchemy\engine\base.py", line 1418, in execute
    return meth(
  File "C:\Users\bharg\AppData\Roaming\Python\Python310\site-packages\sqlalchemy\sql\elements.py", line 515, in _execute_on_connection
    return connection._execute_clauseelement(
  File "C:\Users\bharg\AppData\Roaming\Python\Python310\site-packages\sqlalchemy\engine\base.py", line 1640, in _execute_clauseelement
    ret = self._execute_context(
  File "C:\Users\bharg\AppData\Roaming\Python\Python310\site-packages\sqlalchemy\engine\base.py", line 1846, in _execute_context
    return self._exec_single_context(
  File "C:\Users\bharg\AppData\Roaming\Python\Python310\site-packages\sqlalchemy\engine\base.py", line 1986, in _exec_single_context
    self._handle_dbapi_exception(
  File "C:\Users\bharg\AppData\Roaming\Python\Python310\site-packages\sqlalchemy\engine\base.py", line 2353, in _handle_dbapi_exception
    raise sqlalchemy_exception.with_traceback(exc_info[2]) from e
  File "C:\Users\bharg\AppData\Roaming\Python\Python310\site-packages\sqlalchemy\engine\base.py", line 1967, in _exec_single_context
    self.dialect.do_execute(
  File "C:\Users\bharg\AppData\Roaming\Python\Python310\site-packages\sqlalchemy\engine\default.py", line 924, in do_execute
    cursor.execute(statement, parameters)
sqlalchemy.exc.ProgrammingError: (psycopg2.errors.UndefinedColumn) column expenses.group_id does not exist
LINE 1: SELECT expenses.id, expenses.creator_id, expenses.group_id, ...
                                                 ^

[SQL: SELECT expenses.id, expenses.creator_id, expenses.group_id, expenses.description, expenses.date 
FROM expenses 
WHERE expenses.creator_id = %(creator_id_1)s AND expenses.id = %(id_1)s]
[parameters: {'creator_id_1': '1', 'id_1': 3}]
(Background on this error at: https://sqlalche.me/e/20/f405)
2024-08-31 22:33:53,875 loglevel=INFO   logger=uvicorn.error L265  Shutting down shutdown() call_trace=C:\Users\bharg\AppData\Roaming\Python\Python310\site-packages\uvicorn\server.py
2024-08-31 22:33:53,988 loglevel=INFO   logger=uvicorn.error L65   Waiting for application shutdown. shutdown() call_trace=C:\Users\bharg\AppData\Roaming\Python\Python310\site-packages\uvicorn\lifespan\on.py
2024-08-31 22:33:53,990 loglevel=INFO   logger=uvicorn.error L76   Application shutdown complete. shutdown() call_trace=C:\Users\bharg\AppData\Roaming\Python\Python310\site-packages\uvicorn\lifespan\on.py
2024-08-31 22:33:53,992 loglevel=INFO   logger=uvicorn.error L87   Finished server process [34316] serve() call_trace=C:\Users\bharg\AppData\Roaming\Python\Python310\site-packages\uvicorn\server.py
2024-08-31 22:33:57,639 loglevel=INFO   logger=uvicorn.error L77   Started server process [33204] serve() call_trace=C:\Users\bharg\AppData\Roaming\Python\Python310\site-packages\uvicorn\server.py
2024-08-31 22:33:57,640 loglevel=INFO   logger=uvicorn.error L46   Waiting for application startup. startup() call_trace=C:\Users\bharg\AppData\Roaming\Python\Python310\site-packages\uvicorn\lifespan\on.py
2024-08-31 22:33:57,640 loglevel=INFO   logger=uvicorn.error L60   Application startup complete. startup() call_trace=C:\Users\bharg\AppData\Roaming\Python\Python310\site-packages\uvicorn\lifespan\on.py
2024-08-31 22:33:57,646 loglevel=INFO   logger=uvicorn.error L219  Uvicorn running on http://localhost:8000 (Press CTRL+C to quit) _log_started_message() call_trace=C:\Users\bharg\AppData\Roaming\Python\Python310\site-packages\uvicorn\server.py
2024-08-31 22:34:19,910 loglevel=INFO   logger=uvicorn.access L489  127.0.0.1:50590 - "POST /expenses/ HTTP/1.1" 500 send() call_trace=C:\Users\bharg\AppData\Roaming\Python\Python310\site-packages\uvicorn\protocols\http\httptools_impl.py
2024-08-31 22:34:19,912 loglevel=ERROR  logger=uvicorn.error L424  Exception in ASGI application
 run_asgi() call_trace=C:\Users\bharg\AppData\Roaming\Python\Python310\site-packages\uvicorn\protocols\http\httptools_impl.py
Traceback (most recent call last):
  File "C:\Users\bharg\AppData\Roaming\Python\Python310\site-packages\sqlalchemy\engine\base.py", line 1967, in _exec_single_context
    self.dialect.do_execute(
  File "C:\Users\bharg\AppData\Roaming\Python\Python310\site-packages\sqlalchemy\engine\default.py", line 924, in do_execute
    cursor.execute(statement, parameters)
psycopg2.errors.UndefinedColumn: column "group_id" of relation "expenses" does not exist
LINE 1: INSERT INTO expenses (creator_id, group_id, description, dat...
                                          ^


The above exception was the direct cause of the following exception:

Traceback (most recent call last):
  File "C:\Users\bharg\AppData\Roaming\Python\Python310\site-packages\uvicorn\protocols\http\httptools_impl.py", line 419, in run_asgi
    result = await app(  # type: ignore[func-returns-value]
  File "C:\Users\bharg\AppData\Roaming\Python\Python310\site-packages\uvicorn\middleware\proxy_headers.py", line 84, in __call__
    return await self.app(scope, receive, send)
  File "C:\Users\bharg\AppData\Roaming\Python\Python310\site-packages\fastapi\applications.py", line 1054, in __call__
    await super().__call__(scope, receive, send)
  File "C:\Users\bharg\AppData\Roaming\Python\Python310\site-packages\starlette\applications.py", line 123, in __call__
    await self.middleware_stack(scope, receive, send)
  File "C:\Users\bharg\AppData\Roaming\Python\Python310\site-packages\starlette\middleware\errors.py", line 186, in __call__
    raise exc
  File "C:\Users\bharg\AppData\Roaming\Python\Python310\site-packages\starlette\middleware\errors.py", line 164, in __call__
    await self.app(scope, receive, _send)
  File "C:\Users\bharg\AppData\Roaming\Python\Python310\site-packages\starlette\middleware\exceptions.py", line 62, in __call__
    await wrap_app_handling_exceptions(self.app, conn)(scope, receive, send)
  File "C:\Users\bharg\AppData\Roaming\Python\Python310\site-packages\starlette\_exception_handler.py", line 64, in wrapped_app
    raise exc
  File "C:\Users\bharg\AppData\Roaming\Python\Python310\site-packages\starlette\_exception_handler.py", line 53, in wrapped_app
    await app(scope, receive, sender)
  File "C:\Users\bharg\AppData\Roaming\Python\Python310\site-packages\starlette\routing.py", line 758, in __call__
    await self.middleware_stack(scope, receive, send)
  File "C:\Users\bharg\AppData\Roaming\Python\Python310\site-packages\starlette\routing.py", line 778, in app
    await route.handle(scope, receive, send)
  File "C:\Users\bharg\AppData\Roaming\Python\Python310\site-packages\starlette\routing.py", line 299, in handle
    await self.app(scope, receive, send)
  File "C:\Users\bharg\AppData\Roaming\Python\Python310\site-packages\starlette\routing.py", line 79, in app
    await wrap_app_handling_exceptions(app, request)(scope, receive, send)
  File "C:\Users\bharg\AppData\Roaming\Python\Python310\site-packages\starlette\_exception_handler.py", line 64, in wrapped_app
    raise exc
  File "C:\Users\bharg\AppData\Roaming\Python\Python310\site-packages\starlette\_exception_handler.py", line 53, in wrapped_app
    await app(scope, receive, sender)
  File "C:\Users\bharg\AppData\Roaming\Python\Python310\site-packages\starlette\routing.py", line 74, in app
    response = await func(request)
  File "C:\Users\bharg\AppData\Roaming\Python\Python310\site-packages\fastapi\routing.py", line 278, in app
    raw_response = await run_endpoint_function(
  File "C:\Users\bharg\AppData\Roaming\Python\Python310\site-packages\fastapi\routing.py", line 193, in run_endpoint_function
    return await run_in_threadpool(dependant.call, **values)
  File "C:\Users\bharg\AppData\Roaming\Python\Python310\site-packages\starlette\concurrency.py", line 42, in run_in_threadpool
    return await anyio.to_thread.run_sync(func, *args)
  File "C:\ProgramData\anaconda3\lib\site-packages\anyio\to_thread.py", line 28, in run_sync
    return await get_asynclib().run_sync_in_worker_thread(func, *args, cancellable=cancellable,
  File "C:\ProgramData\anaconda3\lib\site-packages\anyio\_backends\_asyncio.py", line 818, in run_sync_in_worker_thread
    return await future
  File "C:\ProgramData\anaconda3\lib\site-packages\anyio\_backends\_asyncio.py", line 754, in run
    result = context.run(func, *args)
  File "C:\Git_Repos\splitwise\src\api\routes\expenses.py", line 59, in create_expense
    session.commit()
  File "C:\Users\bharg\AppData\Roaming\Python\Python310\site-packages\sqlalchemy\orm\session.py", line 2017, in commit
    trans.commit(_to_root=True)
  File "<string>", line 2, in commit
  File "C:\Users\bharg\AppData\Roaming\Python\Python310\site-packages\sqlalchemy\orm\state_changes.py", line 139, in _go
    ret_value = fn(self, *arg, **kw)
  File "C:\Users\bharg\AppData\Roaming\Python\Python310\site-packages\sqlalchemy\orm\session.py", line 1302, in commit
    self._prepare_impl()
  File "<string>", line 2, in _prepare_impl
  File "C:\Users\bharg\AppData\Roaming\Python\Python310\site-packages\sqlalchemy\orm\state_changes.py", line 139, in _go
    ret_value = fn(self, *arg, **kw)
  File "C:\Users\bharg\AppData\Roaming\Python\Python310\site-packages\sqlalchemy\orm\session.py", line 1277, in _prepare_impl
    self.session.flush()
  File "C:\Users\bharg\AppData\Roaming\Python\Python310\site-packages\sqlalchemy\orm\session.py", line 4341, in flush
    self._flush(objects)
  File "C:\Users\bharg\AppData\Roaming\Python\Python310\site-packages\sqlalchemy\orm\session.py", line 4476, in _flush
    with util.safe_reraise():
  File "C:\Users\bharg\AppData\Roaming\Python\Python310\site-packages\sqlalchemy\util\langhelpers.py", line 146, in __exit__
    raise exc_value.with_traceback(exc_tb)
  File "C:\Users\bharg\AppData\Roaming\Python\Python310\site-packages\sqlalchemy\orm\session.py", line 4437, in _flush
    flush_context.execute()
  File "C:\Users\bharg\AppData\Roaming\Python\Python310\site-packages\sqlalchemy\orm\unitofwork.py", line 466, in execute
    rec.execute(self)
  File "C:\Users\bharg\AppData\Roaming\Python\Python310\site-packages\sqlalchemy\orm\unitofwork.py", line 642, in execute
    util.preloaded.orm_persistence.save_obj(
  File "C:\Users\bharg\AppData\Roaming\Python\Python310\site-packages\sqlalchemy\orm\persistence.py", line 93, in save_obj
    _emit_insert_statements(
  File "C:\Users\bharg\AppData\Roaming\Python\Python310\site-packages\sqlalchemy\orm\persistence.py", line 1233, in _emit_insert_statements
    result = connection.execute(
  File "C:\Users\bharg\AppData\Roaming\Python\Python310\site-packages\sqlalchemy\engine\base.py", line 1418, in execute
    return meth(
  File "C:\Users\bharg\AppData\Roaming\Python\Python310\site-packages\sqlalchemy\sql\elements.py", line 515, in _execute_on_connection
    return connection._execute_clauseelement(
  File "C:\Users\bharg\AppData\Roaming\Python\Python310\site-packages\sqlalchemy\engine\base.py", line 1640, in _execute_clauseelement
    ret = self._execute_context(
  File "C:\Users\bharg\AppData\Roaming\Python\Python310\site-packages\sqlalchemy\engine\base.py", line 1846, in _execute_context
    return self._exec_single_context(
  File "C:\Users\bharg\AppData\Roaming\Python\Python310\site-packages\sqlalchemy\engine\base.py", line 1986, in _exec_single_context
    self._handle_dbapi_exception(
  File "C:\Users\bharg\AppData\Roaming\Python\Python310\site-packages\sqlalchemy\engine\base.py", line 2353, in _handle_dbapi_exception
    raise sqlalchemy_exception.with_traceback(exc_info[2]) from e
  File "C:\Users\bharg\AppData\Roaming\Python\Python310\site-packages\sqlalchemy\engine\base.py", line 1967, in _exec_single_context
    self.dialect.do_execute(
  File "C:\Users\bharg\AppData\Roaming\Python\Python310\site-packages\sqlalchemy\engine\default.py", line 924, in do_execute
    cursor.execute(statement, parameters)
sqlalchemy.exc.ProgrammingError: (psycopg2.errors.UndefinedColumn) column "group_id" of relation "expenses" does not exist
LINE 1: INSERT INTO expenses (creator_id, group_id, description, dat...
                                          ^

[SQL: INSERT INTO expenses (creator_id, group_id, description, date) VALUES (%(creator_id)s, %(group_id)s, %(description)s, %(date)s) RETURNING expenses.id]
[parameters: {'creator_id': '1', 'group_id': None, 'description': 'This is a test group 5', 'date': datetime.datetime(2024, 8, 31, 22, 34, 19, 905619)}]
(Background on this error at: https://sqlalche.me/e/20/f405)
2024-08-31 22:59:57,824 loglevel=INFO   logger=uvicorn.error L265  Shutting down shutdown() call_trace=C:\Users\bharg\AppData\Roaming\Python\Python310\site-packages\uvicorn\server.py
2024-08-31 22:59:57,933 loglevel=INFO   logger=uvicorn.error L65   Waiting for application shutdown. shutdown() call_trace=C:\Users\bharg\AppData\Roaming\Python\Python310\site-packages\uvicorn\lifespan\on.py
2024-08-31 22:59:57,934 loglevel=INFO   logger=uvicorn.error L76   Application shutdown complete. shutdown() call_trace=C:\Users\bharg\AppData\Roaming\Python\Python310\site-packages\uvicorn\lifespan\on.py
2024-08-31 22:59:57,934 loglevel=INFO   logger=uvicorn.error L87   Finished server process [33204] serve() call_trace=C:\Users\bharg\AppData\Roaming\Python\Python310\site-packages\uvicorn\server.py
2024-08-31 18:42:19,184 loglevel=INFO   logger=uvicorn.error L77   Started server process [7] serve() call_trace=/usr/local/lib/python3.11/site-packages/uvicorn/server.py
2024-08-31 18:42:19,186 loglevel=INFO   logger=uvicorn.error L46   Waiting for application startup. startup() call_trace=/usr/local/lib/python3.11/site-packages/uvicorn/lifespan/on.py
2024-08-31 18:42:19,186 loglevel=INFO   logger=uvicorn.error L60   Application startup complete. startup() call_trace=/usr/local/lib/python3.11/site-packages/uvicorn/lifespan/on.py
2024-08-31 18:42:19,187 loglevel=INFO   logger=uvicorn.error L219  Uvicorn running on http://0.0.0.0:8000 (Press CTRL+C to quit) _log_started_message() call_trace=/usr/local/lib/python3.11/site-packages/uvicorn/server.py
2024-08-31 18:47:48,164 loglevel=INFO   logger=uvicorn.access L482  172.24.0.1:39194 - "GET /groups HTTP/1.1" 307 send() call_trace=/usr/local/lib/python3.11/site-packages/uvicorn/protocols/http/h11_impl.py
2024-08-31 18:47:48,178 loglevel=INFO   logger=uvicorn.access L482  172.24.0.1:39194 - "GET /groups/ HTTP/1.1" 200 send() call_trace=/usr/local/lib/python3.11/site-packages/uvicorn/protocols/http/h11_impl.py
2024-08-31 18:48:16,934 loglevel=INFO   logger=uvicorn.access L482  172.24.0.1:53800 - "POST /groups/ HTTP/1.1" 200 send() call_trace=/usr/local/lib/python3.11/site-packages/uvicorn/protocols/http/h11_impl.py
2024-08-31 18:48:49,524 loglevel=INFO   logger=uvicorn.access L482  172.24.0.1:51132 - "PUT /groups/1 HTTP/1.1" 200 send() call_trace=/usr/local/lib/python3.11/site-packages/uvicorn/protocols/http/h11_impl.py
2024-08-31 18:48:54,666 loglevel=INFO   logger=uvicorn.access L482  172.24.0.1:36428 - "GET /groups HTTP/1.1" 307 send() call_trace=/usr/local/lib/python3.11/site-packages/uvicorn/protocols/http/h11_impl.py
2024-08-31 18:48:54,674 loglevel=INFO   logger=uvicorn.access L482  172.24.0.1:36428 - "GET /groups/ HTTP/1.1" 200 send() call_trace=/usr/local/lib/python3.11/site-packages/uvicorn/protocols/http/h11_impl.py
2024-08-31 18:49:27,223 loglevel=INFO   logger=uvicorn.access L482  172.24.0.1:45022 - "POST /groups/ HTTP/1.1" 200 send() call_trace=/usr/local/lib/python3.11/site-packages/uvicorn/protocols/http/h11_impl.py
2024-08-31 18:49:33,498 loglevel=INFO   logger=uvicorn.access L482  172.24.0.1:36694 - "GET /groups HTTP/1.1" 307 send() call_trace=/usr/local/lib/python3.11/site-packages/uvicorn/protocols/http/h11_impl.py
2024-08-31 18:49:33,511 loglevel=INFO   logger=uvicorn.access L482  172.24.0.1:36694 - "GET /groups/ HTTP/1.1" 200 send() call_trace=/usr/local/lib/python3.11/site-packages/uvicorn/protocols/http/h11_impl.py
2024-08-31 18:50:16,222 loglevel=INFO   logger=uvicorn.access L482  172.24.0.1:57390 - "PUT /groups/2 HTTP/1.1" 200 send() call_trace=/usr/local/lib/python3.11/site-packages/uvicorn/protocols/http/h11_impl.py
2024-08-31 18:50:54,218 loglevel=INFO   logger=uvicorn.access L482  172.24.0.1:48664 - "PUT /groups/2 HTTP/1.1" 200 send() call_trace=/usr/local/lib/python3.11/site-packages/uvicorn/protocols/http/h11_impl.py
2024-08-31 18:50:59,594 loglevel=INFO   logger=uvicorn.access L482  172.24.0.1:48674 - "GET /groups HTTP/1.1" 307 send() call_trace=/usr/local/lib/python3.11/site-packages/uvicorn/protocols/http/h11_impl.py
2024-08-31 18:50:59,607 loglevel=INFO   logger=uvicorn.access L482  172.24.0.1:48674 - "GET /groups/ HTTP/1.1" 200 send() call_trace=/usr/local/lib/python3.11/site-packages/uvicorn/protocols/http/h11_impl.py
2024-08-31 18:51:29,177 loglevel=INFO   logger=uvicorn.access L482  172.24.0.1:60652 - "GET /groups/1 HTTP/1.1" 200 send() call_trace=/usr/local/lib/python3.11/site-packages/uvicorn/protocols/http/h11_impl.py
2024-08-31 18:51:38,035 loglevel=INFO   logger=uvicorn.access L482  172.24.0.1:59744 - "GET /groups/2 HTTP/1.1" 200 send() call_trace=/usr/local/lib/python3.11/site-packages/uvicorn/protocols/http/h11_impl.py
2024-08-31 18:51:45,030 loglevel=INFO   logger=uvicorn.access L482  172.24.0.1:44240 - "GET /groups HTTP/1.1" 307 send() call_trace=/usr/local/lib/python3.11/site-packages/uvicorn/protocols/http/h11_impl.py
2024-08-31 18:51:45,039 loglevel=INFO   logger=uvicorn.access L482  172.24.0.1:44240 - "GET /groups/ HTTP/1.1" 200 send() call_trace=/usr/local/lib/python3.11/site-packages/uvicorn/protocols/http/h11_impl.py
2024-08-31 18:55:12,051 loglevel=INFO   logger=uvicorn.access L482  172.24.0.1:44070 - "POST /expenses/ HTTP/1.1" 500 send() call_trace=/usr/local/lib/python3.11/site-packages/uvicorn/protocols/http/h11_impl.py
2024-08-31 18:55:12,052 loglevel=ERROR  logger=uvicorn.error L417  Exception in ASGI application
 run_asgi() call_trace=/usr/local/lib/python3.11/site-packages/uvicorn/protocols/http/h11_impl.py
Traceback (most recent call last):
  File "/usr/local/lib/python3.11/site-packages/sqlalchemy/engine/base.py", line 1967, in _exec_single_context
    self.dialect.do_execute(
  File "/usr/local/lib/python3.11/site-packages/sqlalchemy/engine/default.py", line 924, in do_execute
    cursor.execute(statement, parameters)
psycopg2.errors.ForeignKeyViolation: insert or update on table "expenses" violates foreign key constraint "expenses_group_id_fkey"
DETAIL:  Key (group_id)=(5) is not present in table "groups".


The above exception was the direct cause of the following exception:

Traceback (most recent call last):
  File "/usr/local/lib/python3.11/site-packages/uvicorn/protocols/http/h11_impl.py", line 412, in run_asgi
    result = await app(  # type: ignore[func-returns-value]
             ^^^^^^^^^^^^^^^^^^^^^^^^^^^^^^^^^^^^^^^^^^^^^^
  File "/usr/local/lib/python3.11/site-packages/uvicorn/middleware/proxy_headers.py", line 84, in __call__
    return await self.app(scope, receive, send)
           ^^^^^^^^^^^^^^^^^^^^^^^^^^^^^^^^^^^^
  File "/usr/local/lib/python3.11/site-packages/fastapi/applications.py", line 1054, in __call__
    await super().__call__(scope, receive, send)
  File "/usr/local/lib/python3.11/site-packages/starlette/applications.py", line 123, in __call__
    await self.middleware_stack(scope, receive, send)
  File "/usr/local/lib/python3.11/site-packages/starlette/middleware/errors.py", line 186, in __call__
    raise exc
  File "/usr/local/lib/python3.11/site-packages/starlette/middleware/errors.py", line 164, in __call__
    await self.app(scope, receive, _send)
  File "/usr/local/lib/python3.11/site-packages/starlette/middleware/exceptions.py", line 62, in __call__
    await wrap_app_handling_exceptions(self.app, conn)(scope, receive, send)
  File "/usr/local/lib/python3.11/site-packages/starlette/_exception_handler.py", line 64, in wrapped_app
    raise exc
  File "/usr/local/lib/python3.11/site-packages/starlette/_exception_handler.py", line 53, in wrapped_app
    await app(scope, receive, sender)
  File "/usr/local/lib/python3.11/site-packages/starlette/routing.py", line 758, in __call__
    await self.middleware_stack(scope, receive, send)
  File "/usr/local/lib/python3.11/site-packages/starlette/routing.py", line 778, in app
    await route.handle(scope, receive, send)
  File "/usr/local/lib/python3.11/site-packages/starlette/routing.py", line 299, in handle
    await self.app(scope, receive, send)
  File "/usr/local/lib/python3.11/site-packages/starlette/routing.py", line 79, in app
    await wrap_app_handling_exceptions(app, request)(scope, receive, send)
  File "/usr/local/lib/python3.11/site-packages/starlette/_exception_handler.py", line 64, in wrapped_app
    raise exc
  File "/usr/local/lib/python3.11/site-packages/starlette/_exception_handler.py", line 53, in wrapped_app
    await app(scope, receive, sender)
  File "/usr/local/lib/python3.11/site-packages/starlette/routing.py", line 74, in app
    response = await func(request)
               ^^^^^^^^^^^^^^^^^^^
  File "/usr/local/lib/python3.11/site-packages/fastapi/routing.py", line 278, in app
    raw_response = await run_endpoint_function(
                   ^^^^^^^^^^^^^^^^^^^^^^^^^^^^
  File "/usr/local/lib/python3.11/site-packages/fastapi/routing.py", line 193, in run_endpoint_function
    return await run_in_threadpool(dependant.call, **values)
           ^^^^^^^^^^^^^^^^^^^^^^^^^^^^^^^^^^^^^^^^^^^^^^^^^
  File "/usr/local/lib/python3.11/site-packages/starlette/concurrency.py", line 42, in run_in_threadpool
    return await anyio.to_thread.run_sync(func, *args)
           ^^^^^^^^^^^^^^^^^^^^^^^^^^^^^^^^^^^^^^^^^^^
  File "/usr/local/lib/python3.11/site-packages/anyio/to_thread.py", line 56, in run_sync
    return await get_async_backend().run_sync_in_worker_thread(
           ^^^^^^^^^^^^^^^^^^^^^^^^^^^^^^^^^^^^^^^^^^^^^^^^^^^^
  File "/usr/local/lib/python3.11/site-packages/anyio/_backends/_asyncio.py", line 2177, in run_sync_in_worker_thread
    return await future
           ^^^^^^^^^^^^
  File "/usr/local/lib/python3.11/site-packages/anyio/_backends/_asyncio.py", line 859, in run
    result = context.run(func, *args)
             ^^^^^^^^^^^^^^^^^^^^^^^^
  File "/app/src/api/routes/expenses.py", line 61, in create_expense
    session.commit()
  File "/usr/local/lib/python3.11/site-packages/sqlalchemy/orm/session.py", line 2017, in commit
    trans.commit(_to_root=True)
  File "<string>", line 2, in commit
  File "/usr/local/lib/python3.11/site-packages/sqlalchemy/orm/state_changes.py", line 139, in _go
    ret_value = fn(self, *arg, **kw)
                ^^^^^^^^^^^^^^^^^^^^
  File "/usr/local/lib/python3.11/site-packages/sqlalchemy/orm/session.py", line 1302, in commit
    self._prepare_impl()
  File "<string>", line 2, in _prepare_impl
  File "/usr/local/lib/python3.11/site-packages/sqlalchemy/orm/state_changes.py", line 139, in _go
    ret_value = fn(self, *arg, **kw)
                ^^^^^^^^^^^^^^^^^^^^
  File "/usr/local/lib/python3.11/site-packages/sqlalchemy/orm/session.py", line 1277, in _prepare_impl
    self.session.flush()
  File "/usr/local/lib/python3.11/site-packages/sqlalchemy/orm/session.py", line 4341, in flush
    self._flush(objects)
  File "/usr/local/lib/python3.11/site-packages/sqlalchemy/orm/session.py", line 4476, in _flush
    with util.safe_reraise():
  File "/usr/local/lib/python3.11/site-packages/sqlalchemy/util/langhelpers.py", line 146, in __exit__
    raise exc_value.with_traceback(exc_tb)
  File "/usr/local/lib/python3.11/site-packages/sqlalchemy/orm/session.py", line 4437, in _flush
    flush_context.execute()
  File "/usr/local/lib/python3.11/site-packages/sqlalchemy/orm/unitofwork.py", line 466, in execute
    rec.execute(self)
  File "/usr/local/lib/python3.11/site-packages/sqlalchemy/orm/unitofwork.py", line 642, in execute
    util.preloaded.orm_persistence.save_obj(
  File "/usr/local/lib/python3.11/site-packages/sqlalchemy/orm/persistence.py", line 93, in save_obj
    _emit_insert_statements(
  File "/usr/local/lib/python3.11/site-packages/sqlalchemy/orm/persistence.py", line 1233, in _emit_insert_statements
    result = connection.execute(
             ^^^^^^^^^^^^^^^^^^^
  File "/usr/local/lib/python3.11/site-packages/sqlalchemy/engine/base.py", line 1418, in execute
    return meth(
           ^^^^^
  File "/usr/local/lib/python3.11/site-packages/sqlalchemy/sql/elements.py", line 515, in _execute_on_connection
    return connection._execute_clauseelement(
           ^^^^^^^^^^^^^^^^^^^^^^^^^^^^^^^^^^
  File "/usr/local/lib/python3.11/site-packages/sqlalchemy/engine/base.py", line 1640, in _execute_clauseelement
    ret = self._execute_context(
          ^^^^^^^^^^^^^^^^^^^^^^
  File "/usr/local/lib/python3.11/site-packages/sqlalchemy/engine/base.py", line 1846, in _execute_context
    return self._exec_single_context(
           ^^^^^^^^^^^^^^^^^^^^^^^^^^
  File "/usr/local/lib/python3.11/site-packages/sqlalchemy/engine/base.py", line 1986, in _exec_single_context
    self._handle_dbapi_exception(
  File "/usr/local/lib/python3.11/site-packages/sqlalchemy/engine/base.py", line 2353, in _handle_dbapi_exception
    raise sqlalchemy_exception.with_traceback(exc_info[2]) from e
  File "/usr/local/lib/python3.11/site-packages/sqlalchemy/engine/base.py", line 1967, in _exec_single_context
    self.dialect.do_execute(
  File "/usr/local/lib/python3.11/site-packages/sqlalchemy/engine/default.py", line 924, in do_execute
    cursor.execute(statement, parameters)
sqlalchemy.exc.IntegrityError: (psycopg2.errors.ForeignKeyViolation) insert or update on table "expenses" violates foreign key constraint "expenses_group_id_fkey"
DETAIL:  Key (group_id)=(5) is not present in table "groups".

[SQL: INSERT INTO expenses (creator_id, group_id, description, date) VALUES (%(creator_id)s, %(group_id)s, %(description)s, %(date)s) RETURNING expenses.id]
[parameters: {'creator_id': '1', 'group_id': 5, 'description': 'This is a test group 5', 'date': datetime.datetime(2024, 8, 31, 18, 55, 12, 48788)}]
(Background on this error at: https://sqlalche.me/e/20/gkpj)
2024-08-31 18:55:40,160 loglevel=INFO   logger=uvicorn.access L482  172.24.0.1:41104 - "POST /expenses/ HTTP/1.1" 200 send() call_trace=/usr/local/lib/python3.11/site-packages/uvicorn/protocols/http/h11_impl.py
2024-08-31 18:58:13,786 loglevel=INFO   logger=uvicorn.access L482  172.24.0.1:43320 - "POST /expenses/ HTTP/1.1" 200 send() call_trace=/usr/local/lib/python3.11/site-packages/uvicorn/protocols/http/h11_impl.py
2024-08-31 18:58:38,615 loglevel=INFO   logger=uvicorn.access L482  172.24.0.1:53256 - "POST /expenses/ HTTP/1.1" 200 send() call_trace=/usr/local/lib/python3.11/site-packages/uvicorn/protocols/http/h11_impl.py
2024-08-31 18:59:27,575 loglevel=INFO   logger=uvicorn.access L482  172.24.0.1:42512 - "POST /expenses/ HTTP/1.1" 200 send() call_trace=/usr/local/lib/python3.11/site-packages/uvicorn/protocols/http/h11_impl.py
2024-08-31 19:02:34,717 loglevel=INFO   logger=uvicorn.access L482  172.24.0.1:33258 - "POST /expenses/ HTTP/1.1" 200 send() call_trace=/usr/local/lib/python3.11/site-packages/uvicorn/protocols/http/h11_impl.py
2024-08-31 19:05:21,850 loglevel=INFO   logger=uvicorn.access L482  172.24.0.1:43434 - "DELETE /expenses/6 HTTP/1.1" 500 send() call_trace=/usr/local/lib/python3.11/site-packages/uvicorn/protocols/http/h11_impl.py
2024-08-31 19:05:21,851 loglevel=ERROR  logger=uvicorn.error L417  Exception in ASGI application
 run_asgi() call_trace=/usr/local/lib/python3.11/site-packages/uvicorn/protocols/http/h11_impl.py
Traceback (most recent call last):
  File "/usr/local/lib/python3.11/site-packages/sqlalchemy/engine/base.py", line 1936, in _exec_single_context
    self.dialect.do_executemany(
  File "/usr/local/lib/python3.11/site-packages/sqlalchemy/dialects/postgresql/psycopg2.py", line 794, in do_executemany
    cursor.executemany(statement, parameters)
psycopg2.errors.NotNullViolation: null value in column "expense_id" of relation "expense_breakdowns" violates not-null constraint
DETAIL:  Failing row contains (11, null, 1, 4, 15, f).


The above exception was the direct cause of the following exception:

Traceback (most recent call last):
  File "/usr/local/lib/python3.11/site-packages/uvicorn/protocols/http/h11_impl.py", line 412, in run_asgi
    result = await app(  # type: ignore[func-returns-value]
             ^^^^^^^^^^^^^^^^^^^^^^^^^^^^^^^^^^^^^^^^^^^^^^
  File "/usr/local/lib/python3.11/site-packages/uvicorn/middleware/proxy_headers.py", line 84, in __call__
    return await self.app(scope, receive, send)
           ^^^^^^^^^^^^^^^^^^^^^^^^^^^^^^^^^^^^
  File "/usr/local/lib/python3.11/site-packages/fastapi/applications.py", line 1054, in __call__
    await super().__call__(scope, receive, send)
  File "/usr/local/lib/python3.11/site-packages/starlette/applications.py", line 123, in __call__
    await self.middleware_stack(scope, receive, send)
  File "/usr/local/lib/python3.11/site-packages/starlette/middleware/errors.py", line 186, in __call__
    raise exc
  File "/usr/local/lib/python3.11/site-packages/starlette/middleware/errors.py", line 164, in __call__
    await self.app(scope, receive, _send)
  File "/usr/local/lib/python3.11/site-packages/starlette/middleware/exceptions.py", line 62, in __call__
    await wrap_app_handling_exceptions(self.app, conn)(scope, receive, send)
  File "/usr/local/lib/python3.11/site-packages/starlette/_exception_handler.py", line 64, in wrapped_app
    raise exc
  File "/usr/local/lib/python3.11/site-packages/starlette/_exception_handler.py", line 53, in wrapped_app
    await app(scope, receive, sender)
  File "/usr/local/lib/python3.11/site-packages/starlette/routing.py", line 758, in __call__
    await self.middleware_stack(scope, receive, send)
  File "/usr/local/lib/python3.11/site-packages/starlette/routing.py", line 778, in app
    await route.handle(scope, receive, send)
  File "/usr/local/lib/python3.11/site-packages/starlette/routing.py", line 299, in handle
    await self.app(scope, receive, send)
  File "/usr/local/lib/python3.11/site-packages/starlette/routing.py", line 79, in app
    await wrap_app_handling_exceptions(app, request)(scope, receive, send)
  File "/usr/local/lib/python3.11/site-packages/starlette/_exception_handler.py", line 64, in wrapped_app
    raise exc
  File "/usr/local/lib/python3.11/site-packages/starlette/_exception_handler.py", line 53, in wrapped_app
    await app(scope, receive, sender)
  File "/usr/local/lib/python3.11/site-packages/starlette/routing.py", line 74, in app
    response = await func(request)
               ^^^^^^^^^^^^^^^^^^^
  File "/usr/local/lib/python3.11/site-packages/fastapi/routing.py", line 278, in app
    raw_response = await run_endpoint_function(
                   ^^^^^^^^^^^^^^^^^^^^^^^^^^^^
  File "/usr/local/lib/python3.11/site-packages/fastapi/routing.py", line 193, in run_endpoint_function
    return await run_in_threadpool(dependant.call, **values)
           ^^^^^^^^^^^^^^^^^^^^^^^^^^^^^^^^^^^^^^^^^^^^^^^^^
  File "/usr/local/lib/python3.11/site-packages/starlette/concurrency.py", line 42, in run_in_threadpool
    return await anyio.to_thread.run_sync(func, *args)
           ^^^^^^^^^^^^^^^^^^^^^^^^^^^^^^^^^^^^^^^^^^^
  File "/usr/local/lib/python3.11/site-packages/anyio/to_thread.py", line 56, in run_sync
    return await get_async_backend().run_sync_in_worker_thread(
           ^^^^^^^^^^^^^^^^^^^^^^^^^^^^^^^^^^^^^^^^^^^^^^^^^^^^
  File "/usr/local/lib/python3.11/site-packages/anyio/_backends/_asyncio.py", line 2177, in run_sync_in_worker_thread
    return await future
           ^^^^^^^^^^^^
  File "/usr/local/lib/python3.11/site-packages/anyio/_backends/_asyncio.py", line 859, in run
    result = context.run(func, *args)
             ^^^^^^^^^^^^^^^^^^^^^^^^
  File "/app/src/api/routes/expenses.py", line 72, in delete_group
    session.commit()
  File "/usr/local/lib/python3.11/site-packages/sqlalchemy/orm/session.py", line 2017, in commit
    trans.commit(_to_root=True)
  File "<string>", line 2, in commit
  File "/usr/local/lib/python3.11/site-packages/sqlalchemy/orm/state_changes.py", line 139, in _go
    ret_value = fn(self, *arg, **kw)
                ^^^^^^^^^^^^^^^^^^^^
  File "/usr/local/lib/python3.11/site-packages/sqlalchemy/orm/session.py", line 1302, in commit
    self._prepare_impl()
  File "<string>", line 2, in _prepare_impl
  File "/usr/local/lib/python3.11/site-packages/sqlalchemy/orm/state_changes.py", line 139, in _go
    ret_value = fn(self, *arg, **kw)
                ^^^^^^^^^^^^^^^^^^^^
  File "/usr/local/lib/python3.11/site-packages/sqlalchemy/orm/session.py", line 1277, in _prepare_impl
    self.session.flush()
  File "/usr/local/lib/python3.11/site-packages/sqlalchemy/orm/session.py", line 4341, in flush
    self._flush(objects)
  File "/usr/local/lib/python3.11/site-packages/sqlalchemy/orm/session.py", line 4476, in _flush
    with util.safe_reraise():
  File "/usr/local/lib/python3.11/site-packages/sqlalchemy/util/langhelpers.py", line 146, in __exit__
    raise exc_value.with_traceback(exc_tb)
  File "/usr/local/lib/python3.11/site-packages/sqlalchemy/orm/session.py", line 4437, in _flush
    flush_context.execute()
  File "/usr/local/lib/python3.11/site-packages/sqlalchemy/orm/unitofwork.py", line 466, in execute
    rec.execute(self)
  File "/usr/local/lib/python3.11/site-packages/sqlalchemy/orm/unitofwork.py", line 642, in execute
    util.preloaded.orm_persistence.save_obj(
  File "/usr/local/lib/python3.11/site-packages/sqlalchemy/orm/persistence.py", line 85, in save_obj
    _emit_update_statements(
  File "/usr/local/lib/python3.11/site-packages/sqlalchemy/orm/persistence.py", line 912, in _emit_update_statements
    c = connection.execute(
        ^^^^^^^^^^^^^^^^^^^
  File "/usr/local/lib/python3.11/site-packages/sqlalchemy/engine/base.py", line 1418, in execute
    return meth(
           ^^^^^
  File "/usr/local/lib/python3.11/site-packages/sqlalchemy/sql/elements.py", line 515, in _execute_on_connection
    return connection._execute_clauseelement(
           ^^^^^^^^^^^^^^^^^^^^^^^^^^^^^^^^^^
  File "/usr/local/lib/python3.11/site-packages/sqlalchemy/engine/base.py", line 1640, in _execute_clauseelement
    ret = self._execute_context(
          ^^^^^^^^^^^^^^^^^^^^^^
  File "/usr/local/lib/python3.11/site-packages/sqlalchemy/engine/base.py", line 1846, in _execute_context
    return self._exec_single_context(
           ^^^^^^^^^^^^^^^^^^^^^^^^^^
  File "/usr/local/lib/python3.11/site-packages/sqlalchemy/engine/base.py", line 1986, in _exec_single_context
    self._handle_dbapi_exception(
  File "/usr/local/lib/python3.11/site-packages/sqlalchemy/engine/base.py", line 2353, in _handle_dbapi_exception
    raise sqlalchemy_exception.with_traceback(exc_info[2]) from e
  File "/usr/local/lib/python3.11/site-packages/sqlalchemy/engine/base.py", line 1936, in _exec_single_context
    self.dialect.do_executemany(
  File "/usr/local/lib/python3.11/site-packages/sqlalchemy/dialects/postgresql/psycopg2.py", line 794, in do_executemany
    cursor.executemany(statement, parameters)
sqlalchemy.exc.IntegrityError: (psycopg2.errors.NotNullViolation) null value in column "expense_id" of relation "expense_breakdowns" violates not-null constraint
DETAIL:  Failing row contains (11, null, 1, 4, 15, f).

[SQL: UPDATE expense_breakdowns SET expense_id=%(expense_id)s WHERE expense_breakdowns.id = %(expense_breakdowns_id)s]
[parameters: [{'expense_id': None, 'expense_breakdowns_id': 11}, {'expense_id': None, 'expense_breakdowns_id': 12}, {'expense_id': None, 'expense_breakdowns_id': 13}]]
(Background on this error at: https://sqlalche.me/e/20/gkpj)
2024-08-31 19:08:40,668 loglevel=INFO   logger=uvicorn.access L482  172.24.0.1:47966 - "DELETE /groups/2 HTTP/1.1" 200 send() call_trace=/usr/local/lib/python3.11/site-packages/uvicorn/protocols/http/h11_impl.py
2024-08-31 19:19:56,729 loglevel=INFO   logger=uvicorn.error L77   Started server process [7] serve() call_trace=/usr/local/lib/python3.11/site-packages/uvicorn/server.py
2024-08-31 19:19:56,730 loglevel=INFO   logger=uvicorn.error L46   Waiting for application startup. startup() call_trace=/usr/local/lib/python3.11/site-packages/uvicorn/lifespan/on.py
2024-08-31 19:19:56,731 loglevel=INFO   logger=uvicorn.error L60   Application startup complete. startup() call_trace=/usr/local/lib/python3.11/site-packages/uvicorn/lifespan/on.py
2024-08-31 19:19:56,731 loglevel=INFO   logger=uvicorn.error L219  Uvicorn running on http://0.0.0.0:8000 (Press CTRL+C to quit) _log_started_message() call_trace=/usr/local/lib/python3.11/site-packages/uvicorn/server.py
2024-08-31 19:20:29,196 loglevel=INFO   logger=uvicorn.access L482  172.25.0.1:36368 - "GET /groups HTTP/1.1" 307 send() call_trace=/usr/local/lib/python3.11/site-packages/uvicorn/protocols/http/h11_impl.py
2024-08-31 19:20:29,206 loglevel=INFO   logger=uvicorn.access L482  172.25.0.1:36368 - "GET /groups/ HTTP/1.1" 200 send() call_trace=/usr/local/lib/python3.11/site-packages/uvicorn/protocols/http/h11_impl.py
2024-08-31 19:20:37,389 loglevel=INFO   logger=uvicorn.access L482  172.25.0.1:46664 - "POST /groups/ HTTP/1.1" 200 send() call_trace=/usr/local/lib/python3.11/site-packages/uvicorn/protocols/http/h11_impl.py
2024-08-31 19:20:52,385 loglevel=INFO   logger=uvicorn.access L482  172.25.0.1:44120 - "POST /groups/ HTTP/1.1" 200 send() call_trace=/usr/local/lib/python3.11/site-packages/uvicorn/protocols/http/h11_impl.py
2024-08-31 19:21:00,770 loglevel=INFO   logger=uvicorn.access L482  172.25.0.1:51926 - "GET /groups HTTP/1.1" 307 send() call_trace=/usr/local/lib/python3.11/site-packages/uvicorn/protocols/http/h11_impl.py
2024-08-31 19:21:00,782 loglevel=INFO   logger=uvicorn.access L482  172.25.0.1:51926 - "GET /groups/ HTTP/1.1" 200 send() call_trace=/usr/local/lib/python3.11/site-packages/uvicorn/protocols/http/h11_impl.py
2024-08-31 19:21:20,364 loglevel=INFO   logger=uvicorn.access L482  172.25.0.1:51634 - "PUT /groups/2 HTTP/1.1" 200 send() call_trace=/usr/local/lib/python3.11/site-packages/uvicorn/protocols/http/h11_impl.py
2024-08-31 19:21:30,093 loglevel=INFO   logger=uvicorn.access L482  172.25.0.1:35578 - "PUT /groups/1 HTTP/1.1" 200 send() call_trace=/usr/local/lib/python3.11/site-packages/uvicorn/protocols/http/h11_impl.py
2024-08-31 19:21:36,011 loglevel=INFO   logger=uvicorn.access L482  172.25.0.1:57818 - "GET /groups HTTP/1.1" 307 send() call_trace=/usr/local/lib/python3.11/site-packages/uvicorn/protocols/http/h11_impl.py
2024-08-31 19:21:36,016 loglevel=INFO   logger=uvicorn.access L482  172.25.0.1:57818 - "GET /groups/ HTTP/1.1" 200 send() call_trace=/usr/local/lib/python3.11/site-packages/uvicorn/protocols/http/h11_impl.py
2024-08-31 19:21:55,099 loglevel=INFO   logger=uvicorn.access L482  172.25.0.1:49406 - "POST /expenses/ HTTP/1.1" 200 send() call_trace=/usr/local/lib/python3.11/site-packages/uvicorn/protocols/http/h11_impl.py
2024-08-31 19:24:16,339 loglevel=INFO   logger=uvicorn.access L482  172.25.0.1:39714 - "POST /expenses/ HTTP/1.1" 200 send() call_trace=/usr/local/lib/python3.11/site-packages/uvicorn/protocols/http/h11_impl.py
2024-08-31 19:29:19,604 loglevel=INFO   logger=uvicorn.access L482  172.25.0.1:34790 - "DELETE /expenses/2 HTTP/1.1" 200 send() call_trace=/usr/local/lib/python3.11/site-packages/uvicorn/protocols/http/h11_impl.py
2024-08-31 20:04:01,463 loglevel=INFO   logger=uvicorn.error L77   Started server process [7] serve() call_trace=/usr/local/lib/python3.11/site-packages/uvicorn/server.py
2024-08-31 20:04:01,464 loglevel=INFO   logger=uvicorn.error L46   Waiting for application startup. startup() call_trace=/usr/local/lib/python3.11/site-packages/uvicorn/lifespan/on.py
2024-08-31 20:04:01,464 loglevel=INFO   logger=uvicorn.error L60   Application startup complete. startup() call_trace=/usr/local/lib/python3.11/site-packages/uvicorn/lifespan/on.py
2024-08-31 20:04:01,465 loglevel=INFO   logger=uvicorn.error L219  Uvicorn running on http://0.0.0.0:8000 (Press CTRL+C to quit) _log_started_message() call_trace=/usr/local/lib/python3.11/site-packages/uvicorn/server.py
2024-08-31 20:04:37,981 loglevel=INFO   logger=uvicorn.access L482  172.25.0.1:56726 - "POST /expenses/ HTTP/1.1" 200 send() call_trace=/usr/local/lib/python3.11/site-packages/uvicorn/protocols/http/h11_impl.py
2024-08-31 20:05:14,004 loglevel=INFO   logger=uvicorn.access L482  172.25.0.1:43570 - "GET /expenses/3 HTTP/1.1" 500 send() call_trace=/usr/local/lib/python3.11/site-packages/uvicorn/protocols/http/h11_impl.py
2024-08-31 20:05:14,005 loglevel=ERROR  logger=uvicorn.error L417  Exception in ASGI application
 run_asgi() call_trace=/usr/local/lib/python3.11/site-packages/uvicorn/protocols/http/h11_impl.py
Traceback (most recent call last):
  File "/usr/local/lib/python3.11/site-packages/uvicorn/protocols/http/h11_impl.py", line 412, in run_asgi
    result = await app(  # type: ignore[func-returns-value]
             ^^^^^^^^^^^^^^^^^^^^^^^^^^^^^^^^^^^^^^^^^^^^^^
  File "/usr/local/lib/python3.11/site-packages/uvicorn/middleware/proxy_headers.py", line 84, in __call__
    return await self.app(scope, receive, send)
           ^^^^^^^^^^^^^^^^^^^^^^^^^^^^^^^^^^^^
  File "/usr/local/lib/python3.11/site-packages/fastapi/applications.py", line 1054, in __call__
    await super().__call__(scope, receive, send)
  File "/usr/local/lib/python3.11/site-packages/starlette/applications.py", line 123, in __call__
    await self.middleware_stack(scope, receive, send)
  File "/usr/local/lib/python3.11/site-packages/starlette/middleware/errors.py", line 186, in __call__
    raise exc
  File "/usr/local/lib/python3.11/site-packages/starlette/middleware/errors.py", line 164, in __call__
    await self.app(scope, receive, _send)
  File "/usr/local/lib/python3.11/site-packages/starlette/middleware/exceptions.py", line 62, in __call__
    await wrap_app_handling_exceptions(self.app, conn)(scope, receive, send)
  File "/usr/local/lib/python3.11/site-packages/starlette/_exception_handler.py", line 64, in wrapped_app
    raise exc
  File "/usr/local/lib/python3.11/site-packages/starlette/_exception_handler.py", line 53, in wrapped_app
    await app(scope, receive, sender)
  File "/usr/local/lib/python3.11/site-packages/starlette/routing.py", line 758, in __call__
    await self.middleware_stack(scope, receive, send)
  File "/usr/local/lib/python3.11/site-packages/starlette/routing.py", line 778, in app
    await route.handle(scope, receive, send)
  File "/usr/local/lib/python3.11/site-packages/starlette/routing.py", line 299, in handle
    await self.app(scope, receive, send)
  File "/usr/local/lib/python3.11/site-packages/starlette/routing.py", line 79, in app
    await wrap_app_handling_exceptions(app, request)(scope, receive, send)
  File "/usr/local/lib/python3.11/site-packages/starlette/_exception_handler.py", line 64, in wrapped_app
    raise exc
  File "/usr/local/lib/python3.11/site-packages/starlette/_exception_handler.py", line 53, in wrapped_app
    await app(scope, receive, sender)
  File "/usr/local/lib/python3.11/site-packages/starlette/routing.py", line 74, in app
    response = await func(request)
               ^^^^^^^^^^^^^^^^^^^
  File "/usr/local/lib/python3.11/site-packages/fastapi/routing.py", line 278, in app
    raw_response = await run_endpoint_function(
                   ^^^^^^^^^^^^^^^^^^^^^^^^^^^^
  File "/usr/local/lib/python3.11/site-packages/fastapi/routing.py", line 193, in run_endpoint_function
    return await run_in_threadpool(dependant.call, **values)
           ^^^^^^^^^^^^^^^^^^^^^^^^^^^^^^^^^^^^^^^^^^^^^^^^^
  File "/usr/local/lib/python3.11/site-packages/starlette/concurrency.py", line 42, in run_in_threadpool
    return await anyio.to_thread.run_sync(func, *args)
           ^^^^^^^^^^^^^^^^^^^^^^^^^^^^^^^^^^^^^^^^^^^
  File "/usr/local/lib/python3.11/site-packages/anyio/to_thread.py", line 56, in run_sync
    return await get_async_backend().run_sync_in_worker_thread(
           ^^^^^^^^^^^^^^^^^^^^^^^^^^^^^^^^^^^^^^^^^^^^^^^^^^^^
  File "/usr/local/lib/python3.11/site-packages/anyio/_backends/_asyncio.py", line 2177, in run_sync_in_worker_thread
    return await future
           ^^^^^^^^^^^^
  File "/usr/local/lib/python3.11/site-packages/anyio/_backends/_asyncio.py", line 859, in run
    result = context.run(func, *args)
             ^^^^^^^^^^^^^^^^^^^^^^^^
  File "/app/src/api/routes/expenses.py", line 104, in get_group
    return ExpenseResponse(id = expense.id, description= expense.description, expense_details=expense_details)
           ^^^^^^^^^^^^^^^^^^^^^^^^^^^^^^^^^^^^^^^^^^^^^^^^^^^^^^^^^^^^^^^^^^^^^^^^^^^^^^^^^^^^^^^^^^^^^^^^^^^
  File "/usr/local/lib/python3.11/site-packages/pydantic/main.py", line 171, in __init__
    self.__pydantic_validator__.validate_python(data, self_instance=self)
pydantic_core._pydantic_core.ValidationError: 1 validation error for ExpenseResponse
group_id
  Field required [type=missing, input_value={'id': 3, 'description': ...eiver_id=4, amount=20)]}, input_type=dict]
    For further information visit https://errors.pydantic.dev/2.6/v/missing
2024-08-31 20:06:28,885 loglevel=INFO   logger=uvicorn.error L77   Started server process [7] serve() call_trace=/usr/local/lib/python3.11/site-packages/uvicorn/server.py
2024-08-31 20:06:28,886 loglevel=INFO   logger=uvicorn.error L46   Waiting for application startup. startup() call_trace=/usr/local/lib/python3.11/site-packages/uvicorn/lifespan/on.py
2024-08-31 20:06:28,887 loglevel=INFO   logger=uvicorn.error L60   Application startup complete. startup() call_trace=/usr/local/lib/python3.11/site-packages/uvicorn/lifespan/on.py
2024-08-31 20:06:28,887 loglevel=INFO   logger=uvicorn.error L219  Uvicorn running on http://0.0.0.0:8000 (Press CTRL+C to quit) _log_started_message() call_trace=/usr/local/lib/python3.11/site-packages/uvicorn/server.py
2024-08-31 20:07:01,625 loglevel=INFO   logger=uvicorn.access L482  172.25.0.1:55978 - "GET /expenses/3 HTTP/1.1" 200 send() call_trace=/usr/local/lib/python3.11/site-packages/uvicorn/protocols/http/h11_impl.py
2024-08-31 20:07:16,796 loglevel=INFO   logger=uvicorn.access L482  172.25.0.1:53478 - "GET /expenses/2 HTTP/1.1" 500 send() call_trace=/usr/local/lib/python3.11/site-packages/uvicorn/protocols/http/h11_impl.py
2024-08-31 20:07:16,797 loglevel=ERROR  logger=uvicorn.error L417  Exception in ASGI application
 run_asgi() call_trace=/usr/local/lib/python3.11/site-packages/uvicorn/protocols/http/h11_impl.py
Traceback (most recent call last):
  File "/usr/local/lib/python3.11/site-packages/uvicorn/protocols/http/h11_impl.py", line 412, in run_asgi
    result = await app(  # type: ignore[func-returns-value]
             ^^^^^^^^^^^^^^^^^^^^^^^^^^^^^^^^^^^^^^^^^^^^^^
  File "/usr/local/lib/python3.11/site-packages/uvicorn/middleware/proxy_headers.py", line 84, in __call__
    return await self.app(scope, receive, send)
           ^^^^^^^^^^^^^^^^^^^^^^^^^^^^^^^^^^^^
  File "/usr/local/lib/python3.11/site-packages/fastapi/applications.py", line 1054, in __call__
    await super().__call__(scope, receive, send)
  File "/usr/local/lib/python3.11/site-packages/starlette/applications.py", line 123, in __call__
    await self.middleware_stack(scope, receive, send)
  File "/usr/local/lib/python3.11/site-packages/starlette/middleware/errors.py", line 186, in __call__
    raise exc
  File "/usr/local/lib/python3.11/site-packages/starlette/middleware/errors.py", line 164, in __call__
    await self.app(scope, receive, _send)
  File "/usr/local/lib/python3.11/site-packages/starlette/middleware/exceptions.py", line 62, in __call__
    await wrap_app_handling_exceptions(self.app, conn)(scope, receive, send)
  File "/usr/local/lib/python3.11/site-packages/starlette/_exception_handler.py", line 64, in wrapped_app
    raise exc
  File "/usr/local/lib/python3.11/site-packages/starlette/_exception_handler.py", line 53, in wrapped_app
    await app(scope, receive, sender)
  File "/usr/local/lib/python3.11/site-packages/starlette/routing.py", line 758, in __call__
    await self.middleware_stack(scope, receive, send)
  File "/usr/local/lib/python3.11/site-packages/starlette/routing.py", line 778, in app
    await route.handle(scope, receive, send)
  File "/usr/local/lib/python3.11/site-packages/starlette/routing.py", line 299, in handle
    await self.app(scope, receive, send)
  File "/usr/local/lib/python3.11/site-packages/starlette/routing.py", line 79, in app
    await wrap_app_handling_exceptions(app, request)(scope, receive, send)
  File "/usr/local/lib/python3.11/site-packages/starlette/_exception_handler.py", line 64, in wrapped_app
    raise exc
  File "/usr/local/lib/python3.11/site-packages/starlette/_exception_handler.py", line 53, in wrapped_app
    await app(scope, receive, sender)
  File "/usr/local/lib/python3.11/site-packages/starlette/routing.py", line 74, in app
    response = await func(request)
               ^^^^^^^^^^^^^^^^^^^
  File "/usr/local/lib/python3.11/site-packages/fastapi/routing.py", line 278, in app
    raw_response = await run_endpoint_function(
                   ^^^^^^^^^^^^^^^^^^^^^^^^^^^^
  File "/usr/local/lib/python3.11/site-packages/fastapi/routing.py", line 193, in run_endpoint_function
    return await run_in_threadpool(dependant.call, **values)
           ^^^^^^^^^^^^^^^^^^^^^^^^^^^^^^^^^^^^^^^^^^^^^^^^^
  File "/usr/local/lib/python3.11/site-packages/starlette/concurrency.py", line 42, in run_in_threadpool
    return await anyio.to_thread.run_sync(func, *args)
           ^^^^^^^^^^^^^^^^^^^^^^^^^^^^^^^^^^^^^^^^^^^
  File "/usr/local/lib/python3.11/site-packages/anyio/to_thread.py", line 56, in run_sync
    return await get_async_backend().run_sync_in_worker_thread(
           ^^^^^^^^^^^^^^^^^^^^^^^^^^^^^^^^^^^^^^^^^^^^^^^^^^^^
  File "/usr/local/lib/python3.11/site-packages/anyio/_backends/_asyncio.py", line 2177, in run_sync_in_worker_thread
    return await future
           ^^^^^^^^^^^^
  File "/usr/local/lib/python3.11/site-packages/anyio/_backends/_asyncio.py", line 859, in run
    result = context.run(func, *args)
             ^^^^^^^^^^^^^^^^^^^^^^^^
  File "/app/src/api/routes/expenses.py", line 99, in get_group
    expense = session.scalars(stmt).one()
              ^^^^^^^^^^^^^^^^^^^^^^^^^^^
  File "/usr/local/lib/python3.11/site-packages/sqlalchemy/engine/result.py", line 1810, in one
    return self._only_one_row(
           ^^^^^^^^^^^^^^^^^^^
  File "/usr/local/lib/python3.11/site-packages/sqlalchemy/engine/result.py", line 752, in _only_one_row
    raise exc.NoResultFound(
sqlalchemy.exc.NoResultFound: No row was found when one was required
2024-08-31 20:07:23,287 loglevel=INFO   logger=uvicorn.access L482  172.25.0.1:58606 - "GET /expenses/1 HTTP/1.1" 200 send() call_trace=/usr/local/lib/python3.11/site-packages/uvicorn/protocols/http/h11_impl.py
